Workbook

Sheet Proyecto
B2: LESTRAL CONSTRUCTORA · CON ELECTROMECÁNICA DEL PACÍFICO (EMP)
B3: 01 Proyecto — EMP Suite HVAC · LoadCalc
B4: Réplica en Excel nativo del motor de carga térmica · rev 2.9.7 (15-sep-2026) · solo módulo LoadCalc
B5: Método Carrier/HAP-style: DET por orientación y barrido horario 8–18h · excluye cuartos limpios, ventilación, ductos, selección de equipo y demás disciplinas.
B7: LEYENDA
B8: Captura (editable) | C8: Fórmula (no editar) | D8: Enlace a otra hoja
B10: DATOS DEL PROYECTO
B11: Proyecto | C11: Proyecto sin nombre
B12: Cliente
B13: Ubicación | C13: Tijuana, B.C.
B14: Ingeniero responsable | C14: Ing. Rodrigo Nuñez Loubet
B15: Fecha | C15: =TODAY() -> 46282
B16: Motor de origen (informativo) | C16: SuiteEmp rev 2.9.7 · LoadCalc (Carrier/HAP-style)
B18: SITIO — CONDICIONES EXTERIORES DE DISEÑO
B19: Sitio | C19: Tijuana | D19: Tijuana / Tecate / Mexicali / Ensenada / Personalizado
B20: Si Personalizado — Temp. bulbo seco ext. (°C) | C20: 35
B21: Si Personalizado — Temp. bulbo húmedo ext. (°C) | C21: 24
B22: Si Personalizado — Altitud (m) | C22: 0
B23: Si Personalizado — Rango diario de temperatura (K) | C23: 11
B25: → DB exterior resuelto (°C) | C25: =IF($C$19="Personalizado",$c$c20,INDEX(Referencia!$D$5:$D$8,MATCH($C$19,Referencia!$B$5:$B$8,0))) -> 35
B26: → WB exterior resuelto (°C) | C26: =IF($C$19="Personalizado",$c$c21,INDEX(Referencia!$E$5:$E$8,MATCH($C$19,Referencia!$B$5:$B$8,0))) -> 24
B27: → Altitud resuelta (m) | C27: =IF($C$19="Personalizado",$c$c22,INDEX(Referencia!$F$5:$F$8,MATCH($C$19,Referencia!$B$5:$B$8,0))) -> 0
B28: → Rango diario resuelto (K) | C28: =IF($C$19="Personalizado",$c$c23,INDEX(Referencia!$G$5:$G$8,MATCH($C$19,Referencia!$B$5:$B$8,0))) -> 11
B29: → Presión atmosférica (kPa) [ASHRAE Fund. cap.1 ec.3] | C29: =101.325*(1-0.0000225577*MAX(0,$C$27))^5.2559 -> 101.325
B30: → Razón de presión (pAtm / 101.325) | C30: =$C$29/101.325 -> 1
B31: → Factor de aire sensible qs (0.34 × razón) | C31: =0.34*$C$30 -> 0.34
B32: → Factor de aire latente ql (0.83 × razón) | C32: =0.83*$C$30 -> 0.83
B34: CONDICIONES INTERIORES Y CONSTANTES DEL MÉTODO
B35: Temp. interior de diseño (°C) | C35: 24
B36: HR interior de diseño (%) | C36: 0.5
B37: Latitud de referencia (°N) | C37: 32
B38: Diversidad de edificio (0.5 – 1.0) | C38: 1
B39: Margen de seguridad (constante) | C39: 0.02
B40: Coeficiente de color/absorción de fachada (b) | C40: 0.78
B41: ΔT de suministro de aire fijo (°C) | C41: 11
B42: Calor de ventilador (% del sensible de espacio) | C42: 0.026
B43: Ganancia en ductos no acondicionados (%) | C43: 0.03
B44: Ganancia sensible por persona (W) | C44: 70
B45: Ganancia latente por persona (W) | C45: 45
B46: OA mínimo por persona (m³/h) — Tabla 45 | C46: 30
...

Sheet Captura_Zonas
B2: LESTRAL CONSTRUCTORA · EMP · ENVOLVENTE POR ZONA — MATERIALES POR MENÚ DESPLEGABLE
B3: 02 Captura de zonas — LoadCalc
B4: Una fila por zona (hasta 10). Todos los inputs numéricos nacen en blanco — captura tu proyecto real; los catálogos (material, espacio, iluminación) traen una selección por omisión editable. Las 8 orientaciones nacen con la zona (rev 2.9.2).
B5: Zona | C5: Área (m²) | D5: Altura (m) | E5: Tipo de espacio | F5: Horas de operación | G5: Material de muro | H5: Muro N (m²) | I5: Muro NE (m²) | J5: Muro E (m²) | K5: Muro SE (m²) | L5: Muro S (m²) | M5: Muro SW (m²) | N5: Muro W (m²) | O5: Muro NW (m²) | P5: Área de techo/ cubierta (m²) | Q5: Material de techo | R5: Material de vidrio | S5: Vidrio N (m²) | T5: Vidrio NE (m²) | U5: Vidrio E (m²) | V5: Vidrio SE (m²) | W5: Vidrio S (m²) | X5: Vidrio SW (m²) | Y5: Vidrio W (m²) | Z5: Vidrio NW (m²) | AA5: Ocupantes (pers) | AB5: Iluminación instalada (W) | AC5: Tipo de iluminación | AD5: Equipo/fuerza instalado (W) | AE5: Infiltración (cambios/h) | AF5: Plafón de retorno | AG5: Oscilación diaria de diseño (°C) | AH5: Notas | AI5: Estado | AJ5: TR pico | AK5: kW pico | AL5: Hora pico
B6: Zona 1 | E6: Oficina | F6: 16 | G6: Block ligero 20 cm + panel 25 mm [DEFAULT] | Q6: Losa hormigón + XPS 50 mm [DEFAULT] | R6: Doble vidrio claro (DGU/termopan) [DEFAULT] | AC6: LED | AF6: Auto | AI6: =IF(C6<=0,"Sin área",IF(SUM(H6:O6)+SUM(S6:Z6)<=0,"Sin envolvente","Completa")) -> Sin área | AJ6: =Calculo!D72 -> 0 | AK6: =Calculo!D73 -> 0 | AL6: =Calculo!D69 -> 8
B7: Zona 2 | E7: Oficina | F7: 16 | G7: Block ligero 20 cm + panel 25 mm [DEFAULT] | Q7: Losa hormigón + XPS 50 mm [DEFAULT] | R7: Doble vidrio claro (DGU/termopan) [DEFAULT] | AC7: LED | AF7: Auto | AI7: =IF(C7<=0,"Sin área",IF(SUM(H7:O7)+SUM(S7:Z7)<=0,"Sin envolvente","Completa")) -> Sin área | AJ7: =Calculo!D144 -> 0 | AK7: =Calculo!D145 -> 0 | AL7: =Calculo!D141 -> 8
B8: Zona 3 | E8: Oficina | F8: 16 | G8: Block ligero 20 cm + panel 25 mm [DEFAULT] | Q8: Losa hormigón + XPS 50 mm [DEFAULT] | R8: Doble vidrio claro (DGU/termopan) [DEFAULT] | AC8: LED | AF8: Auto | AI8: =IF(C8<=0,"Sin área",IF(SUM(H8:O8)+SUM(S8:Z8)<=0,"Sin envolvente","Completa")) -> Sin área | AJ8: =Calculo!D216 -> 0 | AK8: =Calculo!D217 -> 0 | AL8: =Calculo!D213 -> 8
B9: Zona 4 | E9: Oficina | F9: 16 | G9: Block ligero 20 cm + panel 25 mm [DEFAULT] | Q9: Losa hormigón + XPS 50 mm [DEFAULT] | R9: Doble vidrio claro (DGU/termopan) [DEFAULT] | AC9: LED | AF9: Auto | AI9: =IF(C9<=0,"Sin área",IF(SUM(H9:O9)+SUM(S9:Z9)<=0,"Sin envolvente","Completa")) -> Sin área | AJ9: =Calculo!D288 -> 0 | AK9: =Calculo!D289 -> 0 | AL9: =Calculo!D285 -> 8
B10: Zona 5 | E10: Oficina | F10: 16 | G10: Block ligero 20 cm + panel 25 mm [DEFAULT] | Q10: Losa hormigón + XPS 50 mm [DEFAULT] | R10: Doble vidrio claro (DGU/termopan) [DEFAULT] | AC10: LED | AF10: Auto | AI10: =IF(C10<=0,"Sin área",IF(SUM(H10:O10)+SUM(S10:Z10)<=0,"Sin envolvente","Completa")) -> Sin área | AJ10: =Calculo!D360 -> 0 | AK10: =Calculo!D361 -> 0 | AL10: =Calculo!D357 -> 8
B11: Zona 6 | E11: Oficina | F11: 16 | G11: Block ligero 20 cm + panel 25 mm [DEFAULT] | Q11: Losa hormigón + XPS 50 mm [DEFAULT] | R11: Doble vidrio claro (DGU/termopan) [DEFAULT] | AC11: LED | AF11: Auto | AI11: =IF(C11<=0,"Sin área",IF(SUM(H11:O11)+SUM(S11:Z11)<=0,"Sin envolvente","Completa")) -> Sin área | AJ11: =Calculo!D432 -> 0 | AK11: =Calculo!D433 -> 0 | AL11: =Calculo!D429 -> 8
B12: Zona 7 | E12: Oficina | F12: 16 | G12: Block ligero 20 cm + panel 25 mm [DEFAULT] | Q12: Losa hormigón + XPS 50 mm [DEFAULT] | R12: Doble vidrio claro (DGU/termopan) [DEFAULT] | AC12: LED | AF12: Auto | AI12: =IF(C12<=0,"Sin área",IF(SUM(H12:O12)+SUM(S12:Z12)<=0,"Sin envolvente","Completa")) -> Sin área | AJ12: =Calculo!D504 -> 0 | AK12: =Calculo!D505 -> 0 | AL12: =Calculo!D501 -> 8
B13: Zona 8 | E13: Oficina | F13: 16 | G13: Block ligero 20 cm + panel 25 mm [DEFAULT] | Q13: Losa hormigón + XPS 50 mm [DEFAULT] | R13: Doble vidrio claro (DGU/termopan) [DEFAULT] | AC13: LED | AF13: Auto | AI13: =IF(C13<=0,"Sin área",IF(SUM(H13:O13)+SUM(S13:Z13)<=0,"Sin envolvente","Completa")) -> Sin área | AJ13: =Calculo!D576 -> 0 | AK13: =Calculo!D577 -> 0 | AL13: =Calculo!D573 -> 8
B14: Zona 9 | E14: Oficina | F14: 16 | G14: Block ligero 20 cm + panel 25 mm [DEFAULT] | Q14: Losa hormigón + XPS 50 mm [DEFAULT] | R14: Doble vidrio claro (DGU/termopan) [DEFAULT] | AC14: LED | AF14: Auto | AI14: =IF(C14<=0,"Sin área",IF(SUM(H14:O14)+SUM(S14:Z14)<=0,"Sin envolvente","Completa")) -> Sin área | AJ14: =Calculo!D648 -> 0 | AK14: =Calculo!D649 -> 0 | AL14: =Calculo!D645 -> 8
B15: Zona 10 | E15: Oficina | F15: 16 | G15: Block ligero 20 cm + panel 25 mm [DEFAULT] | Q15: Losa hormigón + XPS 50 mm [DEFAULT] | R15: Doble vidrio claro (DGU/termopan) [DEFAULT] | AC15: LED | AF15: Auto | AI15: =IF(C15<=0,"Sin área",IF(SUM(H15:O15)+SUM(S15:Z15)<=0,"Sin envolvente","Completa")) -> Sin área | AJ15: =Calculo!D720 -> 0 | AK15: =Calculo!D721 -> 0 | AL15: =Calculo!D717 -> 8
B18: LESTRAL · EMP | C18: LoadCalc rev 2.9.7 · EMP Suite HVAC / Lestral Constructora — uso interno | AL18: Hoja 2 de 5

Sheet Calculo
C2: LESTRAL CONSTRUCTORA · EMP · FÓRMULAS NATIVAS Y AUDITABLES — SIN MACROS
C3: 03 Cálculo — barrido horario de carga térmica por zona
C4: Toda celda es fórmula nativa trazable a Proyecto / Referencia / Captura_Zonas. La hora pico de cada zona se halla por barrido, no se asume fija (motor Carrier/HAP-style, 8–18h solar).
C5: =Captura_Zonas!B6 -> Zona 1
C6: Área (m²) | D6: =Captura_Zonas!C6 -> 0
C7: Altura (m) | D7: =MAX(0.1,Captura_Zonas!D6) -> 0.1
C8: Volumen (m³) | D8: =D6*D7 -> 0
C9: Tipo de espacio | D9: =Captura_Zonas!E6 -> Oficina
C10: Horas de operación | D10: =Captura_Zonas!F6 -> 16
C11: Rp (L/s·persona) | D11: =INDEX(Referencia!$C$79:$C$88,MATCH(D9,Referencia!$B$79:$B$88,0)) -> 2.5
C12: Ra (L/s·m²) | D12: =INDEX(Referencia!$D$79:$D$88,MATCH(D9,Referencia!$B$79:$B$88,0)) -> 0.3
C13: Diversidad personas | D13: =INDEX(Referencia!$E$79:$E$88,MATCH(D9,Referencia!$B$79:$B$88,0)) -> 0.9
C14: Diversidad luces | D14: =INDEX(Referencia!$F$79:$F$88,MATCH(D9,Referencia!$B$79:$B$88,0)) -> 0.95
C15: Diversidad equipo | D15: =INDEX(Referencia!$G$79:$G$88,MATCH(D9,Referencia!$B$79:$B$88,0)) -> 0.9
C16: K muro (W/m²K) | D16: =INDEX(Referencia!$C$15:$C$43,MATCH(Captura_Zonas!G6,Referencia!$B$15:$B$43,0)) -> 0.849
C17: Peso muro (kg/m²) | D17: =INDEX(Referencia!$D$15:$D$43,MATCH(Captura_Zonas!G6,Referencia!$B$15:$B$43,0)) -> 176
C18: K techo (W/m²K) | D18: =INDEX(Referencia!$C$47:$C$60,MATCH(Captura_Zonas!Q6,Referencia!$B$47:$B$60,0)) -> 0.55
C19: Peso techo (kg/m²) | D19: =INDEX(Referencia!$D$47:$D$60,MATCH(Captura_Zonas!Q6,Referencia!$B$47:$B$60,0)) -> 320
C20: K vidrio (W/m²K) | D20: =INDEX(Referencia!$C$64:$C$75,MATCH(Captura_Zonas!R6,Referencia!$B$64:$B$75,0)) -> 2.8
C21: SHGC vidrio | D21: =INDEX(Referencia!$E$64:$E$75,MATCH(Captura_Zonas!R6,Referencia!$B$64:$B$75,0)) -> 0.7
C22: Masa constructiva wFloor (kg/m² piso) | D22: =IF(D6>0,((Captura_Zonas!H6+Captura_Zonas!I6+Captura_Zonas!J6+Captura_Zonas!K6+Captura_Zonas!L6+Captura_Zonas!M6+Captura_Zonas!N6+Captura_Zonas!O6)*D17+Captura_Zonas!P6*D19+(Captura_Zonas!S6+Captura_Zonas!T6+Captura_Zonas!U6+Captura_Zonas!V6+Captura_Zonas!W6+Captura_Zonas!X6+Captura_Zonas!Y6+Captura_Zonas!Z6)*25)/D6,200) -> 200
C23: Clase de masa | D23: =IF(D22<150,"Ligera",IF(D22<350,"Media","Pesada")) -> Media
C24: Oscilación diaria de diseño (°C) | D24: =MAX(0,Captura_Zonas!AG6) -> 0
C25: Factor de oscilación swingF | D25: =IF(D24<=0,1,MAX(0.75,1-D24*IF(D23="Pesada",0.04,IF(D23="Media",0.03,0.02))*2.5)) -> 1
C26: Almacenamiento solar | D26: =INDEX(Referencia!$C$92:$E$94,MATCH(D10,Referencia!$B$92:$B$94,0),MATCH(D23,{"Ligera","Media","Pesada"},0))*D25 -> 0.66
C27: Almacenamiento luces | D27: =INDEX(Referencia!$C$98:$E$100,MATCH(D10,Referencia!$B$98:$B$100,0),MATCH(D23,{"Ligera","Media","Pesada"},0))*D25 -> 0.7
C28: Almacenamiento personas | D28: =INDEX(Referencia!$C$104:$C$106,MATCH(D10,Referencia!$B$104:$B$106,0)) -> 0.9
C29: Almacenamiento equipo | D29: =INDEX(Referencia!$D$104:$D$106,MATCH(D10,Referencia!$B$104:$B$106,0)) -> 0.9
C30: Multiplicador de iluminación | D30: =IF(Captura_Zonas!AC6="Fluorescente",1.2,1) -> 1
C31: ¿Plafón de retorno? | D31: =IF(Captura_Zonas!AF6="Auto",D7>=3.5,Captura_Zonas!AF6="Sí") -> FALSE
C32: Estratificación (strat) | D32: =IF(D7<=3.2,1,IF(AND(D31,D7>=4),0.7,IF(D7>=5,0.75,IF(D7>=4,0.85,0.92)))) -> 1
C33: Ocupantes (número) | D33: =MAX(0,ROUND(Captura_Zonas!AA6,0)) -> 0
C34: Ocupantes — sensible (W) | D34: =D33*Proyecto!$C$44*D28*D13*Proyecto!$C$38 -> 0
C35: Ocupantes — latente (W) | D35: =D33*Proyecto!$C$45*D13*Proyecto!$C$38 -> 0
C36: Iluminación (W, constante) | D36: =MAX(0,Captura_Zonas!AB6)*D30*D27*D14*Proyecto!$C$38*D32 -> 0
C37: Equipos/fuerza (W, constante) | D37: =MAX(0,Captura_Zonas!AD6)*D29*D15*Proyecto!$C$38 -> 0
C38: Flujo de infiltración (m³/h) | D38: =D8*MAX(0,Captura_Zonas!AE6) -> 0
C39: OA — ASHRAE 62.1 (m³/h) | D39: =(D11*D33+D12*D6)*3.6 -> 0
C40: OA — por persona Tab.45 (m³/h) | D40: =D33*Proyecto!$C$46 -> 0
C41: OA — por área Tab.45 (m³/h) | D41: =D6*Proyecto!$C$47 -> 0
...

Sheet Resultados
B2: LESTRAL CONSTRUCTORA · CON ELECTROMECÁNICA DEL PACÍFICO (EMP) · MEMORIA DE CÁLCULO
B3: 04 Memoria de cálculo — carga térmica LoadCalc
B4: Resumen del proyecto, método y resultados por zona (barrido horario 8–18h). El total es la suma de los picos individuales de zona, no un pico simultáneo de edificio.
B5: DATOS DEL PROYECTO Y MÉTODO
B6: Proyecto | C6: =Proyecto!C11&"" -> Proyecto sin nombre | G6: CAPACIDAD TOTAL DEL PROYECTO
B7: Cliente | C7: =Proyecto!C12&"" | G7: =TEXT(H29,"0.00")&" TR" -> 0.00 TR
B8: Ubicación | C8: =Proyecto!C13&"" -> Tijuana, B.C.
B9: Ingeniero responsable | C9: =Proyecto!C14&"" -> Ing. Rodrigo Nuñez Loubet | G9: =TEXT(G29,"0.00")&" kW totales (sensible + latente)" -> 0.00 kW totales (sensible + latente)
B10: Fecha | C10: =Proyecto!C15 -> 46282 | G10: =TEXT(I29,"#,##0")&" CFM de suministro" -> 0 CFM de suministro
B11: Sitio de diseño | C11: =Proyecto!C19&"" -> Tijuana
B12: Condiciones exteriores (DB / WB / Alt.) | C12: =Proyecto!$C$25&" °C DB · "&Proyecto!$C$26&" °C WB · "&Proyecto!$C$27&" m" -> 35 °C DB · 24 °C WB · 0 m
B13: Método | C13: Carrier/HAP-style · DET por orientación · barrido horario 8–18h (motor LoadCalc rev 2.9.7)
B14: Diversidad de edificio | C14: =Proyecto!$C$38 -> 1
B15: Margen de seguridad aplicado | C15: =Proyecto!$C$39 -> 0.02
B18: Zona | C18: Área (m²) | D18: Hora pico | E18: Sensible (kW) | F18: Latente (kW) | G18: Total (kW) | H18: TR | I18: CFM suministro
B19: =Calculo!C5 -> Zona 1 | C19: =Calculo!D6 -> 0 | D19: =Calculo!D69 -> 8 | E19: =Calculo!D71/1000 -> 0 | F19: =Calculo!D48/1000 -> 0 | G19: =Calculo!D73 -> 0 | H19: =Calculo!D72 -> 0 | I19: =Calculo!D74 -> 0
B20: =Calculo!C77 -> Zona 2 | C20: =Calculo!D78 -> 0 | D20: =Calculo!D141 -> 8 | E20: =Calculo!D143/1000 -> 0 | F20: =Calculo!D120/1000 -> 0 | G20: =Calculo!D145 -> 0 | H20: =Calculo!D144 -> 0 | I20: =Calculo!D146 -> 0
B21: =Calculo!C149 -> Zona 3 | C21: =Calculo!D150 -> 0 | D21: =Calculo!D213 -> 8 | E21: =Calculo!D215/1000 -> 0 | F21: =Calculo!D192/1000 -> 0 | G21: =Calculo!D217 -> 0 | H21: =Calculo!D216 -> 0 | I21: =Calculo!D218 -> 0
B22: =Calculo!C221 -> Zona 4 | C22: =Calculo!D222 -> 0 | D22: =Calculo!D285 -> 8 | E22: =Calculo!D287/1000 -> 0 | F22: =Calculo!D264/1000 -> 0 | G22: =Calculo!D289 -> 0 | H22: =Calculo!D288 -> 0 | I22: =Calculo!D290 -> 0
B23: =Calculo!C293 -> Zona 5 | C23: =Calculo!D294 -> 0 | D23: =Calculo!D357 -> 8 | E23: =Calculo!D359/1000 -> 0 | F23: =Calculo!D336/1000 -> 0 | G23: =Calculo!D361 -> 0 | H23: =Calculo!D360 -> 0 | I23: =Calculo!D362 -> 0
B24: =Calculo!C365 -> Zona 6 | C24: =Calculo!D366 -> 0 | D24: =Calculo!D429 -> 8 | E24: =Calculo!D431/1000 -> 0 | F24: =Calculo!D408/1000 -> 0 | G24: =Calculo!D433 -> 0 | H24: =Calculo!D432 -> 0 | I24: =Calculo!D434 -> 0
B25: =Calculo!C437 -> Zona 7 | C25: =Calculo!D438 -> 0 | D25: =Calculo!D501 -> 8 | E25: =Calculo!D503/1000 -> 0 | F25: =Calculo!D480/1000 -> 0 | G25: =Calculo!D505 -> 0 | H25: =Calculo!D504 -> 0 | I25: =Calculo!D506 -> 0
B26: =Calculo!C509 -> Zona 8 | C26: =Calculo!D510 -> 0 | D26: =Calculo!D573 -> 8 | E26: =Calculo!D575/1000 -> 0 | F26: =Calculo!D552/1000 -> 0 | G26: =Calculo!D577 -> 0 | H26: =Calculo!D576 -> 0 | I26: =Calculo!D578 -> 0
B27: =Calculo!C581 -> Zona 9 | C27: =Calculo!D582 -> 0 | D27: =Calculo!D645 -> 8 | E27: =Calculo!D647/1000 -> 0 | F27: =Calculo!D624/1000 -> 0 | G27: =Calculo!D649 -> 0 | H27: =Calculo!D648 -> 0 | I27: =Calculo!D650 -> 0
B28: =Calculo!C653 -> Zona 10 | C28: =Calculo!D654 -> 0 | D28: =Calculo!D717 -> 8 | E28: =Calculo!D719/1000 -> 0 | F28: =Calculo!D696/1000 -> 0 | G28: =Calculo!D721 -> 0 | H28: =Calculo!D720 -> 0 | I28: =Calculo!D722 -> 0
B29: TOTAL DEL PROYECTO | C29: =SUM(C19:C28) -> 0 | D29: — | E29: =SUM(E19:E28) -> 0 | F29: =SUM(F19:F28) -> 0 | G29: =SUM(G19:G28) -> 0 | H29: =SUM(H19:H28) -> 0 | I29: =SUM(I19:I28) -> 0
B31: Diversidad de edificio aplicada: | C31: =Proyecto!$C$38 -> 1
B32: Margen de seguridad aplicado: | C32: =Proyecto!$C$39 -> 0.02
B34: Nota: el CFM de suministro usa el ΔT fijo de Proyecto (constante histórica HAP.dT), no el punto de rocío del aparato (ADP/SHF/BF) que resuelve el motor completo para selección de equipo — esa etapa queda fuera del alcance de este libro (solo LoadCalc).
B74: LESTRAL · EMP | C74: LoadCalc rev 2.9.7 · EMP Suite HVAC / Lestral Constructora — uso interno | I74: Hoja 4 de 5

Sheet Referencia
B2: LESTRAL CONSTRUCTORA · EMP · CATÁLOGOS Y FACTORES · SOLO CONSULTA
B3: 05 Referencia — tablas del motor LoadCalc rev 2.9.7
B4: Todas las tablas de este libro provienen del código fuente real del motor (constantes RAW/SPACES/SOLAR_ST/SUN_H). Las filas calculadas dependen de Proyecto y se recalculan solas.
B5: SITIOS DE REFERENCIA (SITES)
B6: Clave (dropdown) | C6: Etiqueta | D6: DB ext (°C) | E6: WB ext (°C) | F6: Altitud (m) | G6: Rango diario (K) | H6: Fuente
B7: Tijuana | C7: Tijuana, B.C. (protegido) | D7: 35 | E7: 24 | F7: 0 | G7: 11 | H7: constants.ts · PROTECTED · rango diario 11 K
B8: Tecate | C8: Tecate, B.C. (valle interior) | D8: 40 | E8: 21 | F8: 540 | G8: 16 | H8: supuesto de valle interior · ratificar con fila ASHRAE
B9: Mexicali | C9: Mexicali, B.C. | D9: 46 | E9: 23 | F9: 3 | G9: 17 | H9: referencia de zona desértica · ratificar
B10: Ensenada | C10: Ensenada, B.C. | D10: 30 | E10: 22 | F10: 20 | G10: 8 | H10: referencia costera · ratificar
B13: MATERIALES — MURO (catálogo del motor)
B14: Material | C14: K (W/m²K) | D14: Peso (kg/m²)
B15: Ladrillo macizo 20 cm + enlucido | C15: 2.721 | D15: 435
B16: Ladrillo macizo 30 cm + enlucido | C16: 1.989 | D16: 610
B17: Block hueco 20 cm (arena/grava) | C17: 2.954 | D17: 210
B18: Block 15 cm + aislamiento 25 mm | C18: 0.9 | D18: 160
B19: Hormigón vertido 20 cm | C19: 3.803 | D19: 454
B20: Hormigón 15 cm + XPS 50 mm | C20: 0.55 | D20: 380
B21: Block ligero 20 cm + panel 25 mm [DEFAULT] | C21: 0.849 | D21: 176
B22: Panel sándwich PUR 100 mm | C22: 0.35 | D22: 25
B23: Panel PIR 80 mm | C23: 0.28 | D23: 22
B24: USG Sheetrock + metal stud + R-11 | C24: 0.55 | D24: 28
B25: USG Sheetrock + metal stud + R-13 | C25: 0.45 | D25: 30
B26: USG Sheetrock + stud 150 mm + R-19 | C26: 0.32 | D26: 34
... B43: Tilt-up concreto 20 cm sin aislar | C43: 3.6 | D43: 460
B45: MATERIALES — TECHO / CUBIERTA (catálogo del motor)
B46: Material | C46: K (W/m²K) | D46: Peso (kg/m²)
B47: Losa hormigón + XPS 50 mm [DEFAULT] | C47: 0.55 | D47: 320
B48: Losa hormigón + XPS 100 mm | C48: 0.35 | D48: 330
B49: Cubierta metálica aislada 80 mm | C49: 0.4 | D49: 40
B50: Cubierta panel PIR 100 mm (industrial) | C50: 0.22 | D50: 28
B51: USG cielo + entrepiso + R-30 | C51: 0.28 | D51: 45
B52: USG Sheetrock + ático ventilado R-38 | C52: 0.2 | D52: 40
B53: Teja / loseta + aislamiento 50 mm | C53: 0.65 | D53: 90
B54: Impermeabilizante + lana 75 mm (built-up) | C54: 0.45 | D54: 55
B55: Panel sandwich MgO 50 mm (plafón) | C55: 0.62 | D55: 18
B56: Panel sandwich lana mineral 100 mm (plafón) | C56: 0.42 | D56: 22
B57: Lámina de cubierta con fibra de vidrio 75 mm | C57: 0.52 | D57: 12
B58: Panel sandwich de cubierta PUR 100 mm | C58: 0.23 | D58: 15
... B60: Membrana TPO reflectiva + XPS 75 mm | C60: 0.38 | D60: 25
B62: MATERIALES — VIDRIO (catálogo del motor)
...
