Workbook

Sheet 1. COVER
B2: LESTRAL CONSTRUCTORA Electromecánica del Pacífico (EMP)
B5: INDUSTRIAL TURNKEY PROJECTS • ENGINEERING + CONSTRUCTION + INSTALLATION
B7: TURNKEY CONSTRUCTION PROPOSAL CLEANROOM WORKSHOP RENOVATION
B9: QMX Mexico Workshop Renovation Project • Baja California, Mexico
B11: CLIENT | C11: QMX / QIUSHI
B12: PROJECT | C12: Mexico Cleanroom Workshop Renovation Project
B13: SITE | C13: Baja California, Mexico
B14: BASIS OF QUOTATION | C14: Executive project and bill of quantities dated 10-Sep-2026 (Shanghai Jingdian IFC drawing set)
B15: QUOTATION No. | C15: EMP-QMX-2026-09-CR • Rev. D
B16: DATE | C16: 10 September 2026
B17: VALIDITY | C17: 30 calendar days
B18: CURRENCY | C18: US Dollars (USD)
B19: CONTRACT DURATION | C19: 24 weeks from advance payment
B20: SUBMITTED BY | C20: ING. RODRIGO NUÑEZ LOUBET
B22: TOTAL TURNKEY CONSTRUCTION PRICE (VAT INCLUDED)
B23: ='6. COST SUMMARY'!D21 -> 2369001.8
B25: CONFIDENTIAL PROPOSAL • Prepared exclusively for QMX • Blvd. Insurgentes, Tijuana, Baja California, Mexico Single point of accountability • Engineering, procurement, construction and commissioning under one contract This document supersedes proposal EMP-QMX-2026-08-F1 Rev. C.1 in respect of the scope covered by the 10-Sep-2026 executive project.

Sheet 2. EXECUTIVE SUMMARY
A1: LESTRAL CONSTRUCTORA, S. DE R.L. DE C.V. | ELECTROMECÁNICA DEL PACÍFICO (EMP)
A2: 2. EXECUTIVE SUMMARY
B4: Lestral Constructora / Electromecánica del Pacífico (EMP) is pleased to submit this turnkey construction proposal for the renovation of the QMX workshop in Baja California, Mexico, comprising an ISO-class controlled environment together with its supporting production, inspection, change, transfer and office areas. The proposal has been priced line by line against the executive project issued on 10 September 2026 by Shanghai Jingdian Planning & Architectural Design: architectural, structural, HVAC, plumbing, electrical, fire protection and compressed air drawing sets, together with the bill of quantities in the same package. Every quantity in this quotation is taken directly from that bill of quantities, unit by unit, so that the offer can be compared against the client's own document without re-measurement. The scope covers eight disciplines and 341 priced line items: preliminaries and construction measures; architectural, structural steel and finishes; HVAC and cleanroom air systems; electrical installations; plumbing, water supply and drainage; fire protection and fire alarm; IT, CCTV and access control; and compressed air distribution. EMP acts as a single point of accountability for engineering adaptation, procurement, construction, testing and commissioning. Two matters require the client's attention and are addressed in the Value Engineering section. First, the design specifies equipment at 380 V three-phase, which is not a distribution voltage available in Mexico; the bill of quantities resolves this with a 200 kVA step-down transformer, but re-specifying the equipment at 480/277-220 V removes the transformer entirely. Second, the fire protection design follows Chinese GB codes; Mexican authority approval and plant insurance both work from NFPA. EMP has priced the project exactly as designed, and quantified both alternatives separately so the client can decide on the merits.
B20: COST BY DISCIPLINE
B21: DISCIPLINE | C21: ITEMS | D21: DIRECT COST (USD) | E21: % OF DIRECT
B22: 01 PRELIMINARIES AND CONSTRUCTION MEASURES | C22: 22 | D22: =SUMIF('5. BOQ DETAIL'!$A:$A,"A TOTAL",'5. BOQ DETAIL'!$H:$H) -> 266800 | E22: =IF($D$30=0,0,D22/$D$30) -> 0.14883253
B23: 02 ARCHITECTURAL, STRUCTURE AND FINISHES | C23: 31 | D23: =SUMIF('5. BOQ DETAIL'!$A:$A,"B TOTAL",'5. BOQ DETAIL'!$H:$H) -> 606786.77 | E23: =IF($D$30=0,0,D23/$D$30) -> 0.33849179
B24: 03 HVAC AND CLEANROOM AIR SYSTEMS | C24: 111 | D24: =SUMIF('5. BOQ DETAIL'!$A:$A,"C TOTAL",'5. BOQ DETAIL'!$H:$H) -> 365367 | E24: =IF($D$30=0,0,D24/$D$30) -> 0.20381745
B25: 04 ELECTRICAL INSTALLATIONS | C25: 63 | D25: =SUMIF('5. BOQ DETAIL'!$A:$A,"D TOTAL",'5. BOQ DETAIL'!$H:$H) -> 275378.78 | E25: =IF($D$30=0,0,D25/$D$30) -> 0.15361814
B26: 05 PLUMBING, WATER SUPPLY AND DRAINAGE | C26: 35 | D26: =SUMIF('5. BOQ DETAIL'!$A:$A,"E TOTAL",'5. BOQ DETAIL'!$H:$H) -> 62252.99 | E26: =IF($D$30=0,0,D26/$D$30) -> 0.034727399
B27: 06 FIRE PROTECTION AND FIRE ALARM | C27: 51 | D27: =SUMIF('5. BOQ DETAIL'!$A:$A,"F TOTAL",'5. BOQ DETAIL'!$H:$H) -> 150728.24 | E27: =IF($D$30=0,0,D27/$D$30) -> 0.084082703
B28: 07 IT, CCTV AND ACCESS CONTROL | C28: 20 | D28: =SUMIF('5. BOQ DETAIL'!$A:$A,"G TOTAL",'5. BOQ DETAIL'!$H:$H) -> 34987.99 | E28: =IF($D$30=0,0,D28/$D$30) -> 0.019517808
B29: 08 COMPRESSED AIR DISTRIBUTION | C29: 8 | D29: =SUMIF('5. BOQ DETAIL'!$A:$A,"H TOTAL",'5. BOQ DETAIL'!$H:$H) -> 30317.09 | E29: =IF($D$30=0,0,D29/$D$30) -> 0.016912178
B30: TOTAL DIRECT COST | C30: =SUM(C22:C29) -> 341 | D30: =SUM(D22:D29) -> 1792618.9 | E30: 1
B32: Total price before VAT | C32: ='6. COST SUMMARY'!D19 -> 2193520.1
B33: Total price including 8% VAT | C33: ='6. COST SUMMARY'!D21 -> 2369001.8
B34: Contract duration (weeks) | C34: 24
B35: Value engineering saving identified | C35: ='9. VALUE ENGINEERING'!E16 -> 80869.6
B36: Optimized duration (weeks) | C36: 20

Sheet 3. SCOPE OF WORK
A1: LESTRAL CONSTRUCTORA, S. DE R.L. DE C.V. | ELECTROMECÁNICA DEL PACÍFICO (EMP)
A2: 3. DETAILED SCOPE OF WORK BY SYSTEM AND DISCIPLINE
B4: The scope below is the contractual description of the works. It corresponds item by item to the priced bill of quantities in sheet 5 and to the executive project issued 10-Sep-2026.
B6: A. PRELIMINARIES AND CONSTRUCTION MEASURES
B7: ▪ | C7: Site management, superintendence, safety officer and site administration for the full duration of the works.
B8: ▪ | C8: Temporary site facilities, scaffolding, lifting and rigging, temporary utilities, small tools and site housekeeping.
B9: ▪ | C9: Shop drawings, adaptation of the IFC package to Mexican codes (NOM-001-SEDE-2012, NOM-002-STPS-2010, NFPA references) and production of as-built drawings.
B10: ▪ | C10: Setting out, levels and survey; sample submittals, mock-ups and laboratory testing; quality supervision under an inspection and test plan.
B11: ▪ | C11: Statutory insurance and contributions, protection of finished works, daily progress reporting with photographic record.
B12: ▪ | C12: Indoor air quality testing at completion and fire protection testing, verification and authority sign-off.
B14: B. ARCHITECTURAL, STRUCTURE AND FINISHES
B15: ▪ | C15: Structural steel: columns, beams, purlins, tie rods, struts, access ladders, embedded plates and high-strength bolting, shop primed and erected.
B16: ▪ | C16: Cleanroom envelope in 50 mm rock wool sandwich panel with aluminium profiles and fully sealed joints, including walkable ceiling panel.
B17: ▪ | C17: Lightweight block walls with cement render, dowelling, tie bars, bond beams and lintels; mesh enclosure fencing.
B18: ▪ | C18: Floors: electrostatic-dissipative epoxy system with copper foil grid over epoxy mortar, standard two-component epoxy, anti-slip tile over polyurethane waterproofing.
B19: ▪ | C19: Cleanroom doors (double leaf, single leaf and sliding) with complete hardware; viewing windows in tempered glazing; restroom wood-veneer doors.
B20: ▪ | C20: Restroom fit-out: wall and floor tile, aluminium lay-in ceiling, marble lavatory counter, framed mirror, toilet partitions, grab rails and accessories.
B21: ▪ | C21: Demolition of existing restrooms, partitions and ceilings, with floor repair matched to the adjacent finish.
B23: C. HVAC AND CLEANROOM AIR SYSTEMS
B24: ▪ | C24: Cleanroom air conditioning: high static pressure fan coil units served by a 123.5 kW outdoor condensing unit, with thermostats, refnet manifolds and complete refrigerant distribution.
B25: ▪ | C25: Cleanroom outside air: direct-expansion air handling unit of 2,500 m3/h at 300 Pa external static pressure with its outdoor condensing section, motorized and manual dampers, and differential pressure gauges for the pressure cascade.
B26: ▪ | C26: Non-classified area conditioning: four-way ceiling cassette multi-split indoor units served by a 33.5 kW outdoor unit, and a total heat recovery ventilator for outside air.
B27: ▪ | C27: Ventilation and exhaust: inline and cabinet centrifugal fans, restroom exhaust fans, activated carbon filtration unit for process exhaust, weatherproof louvers and weather caps.
B28: ▪ | C28: Galvanized sheet steel ductwork fabricated and installed to GB 50243-2016 / SMACNA equivalent leakage class, with class B1 flame-retardant elastomeric insulation and canvas flexible connectors.
B29: ▪ | C29: Return air column enclosures, supports and hangers, condensate drainage in UPVC, refrigerant top-up charge and all piping accessories.
B30: ▪ | C30: Automatic control system for the cleanroom HVAC: controllers, field sensors, wiring, programming and commissioning.
B31: ▪ | C31: Testing, adjusting and balancing of all air systems, with documented results per zone.
B33: D. ELECTRICAL INSTALLATIONS
B34: ▪ | C34: Indoor dry-type transformer of 200 kVA, 480 V primary / 380 V secondary, with pad and connections, as specified in the executive project.
B35: ▪ | C35: Eight distribution boards (1APZ, 1AL1, 1AP-KT, 2AC-KT1, 2AC-KT2, 1AC-PW1, 1AC-PW2, 1ALED) per single-line diagram, complete with breakers and terminations, plus modification of existing boards affected by the new layout.
B36: ▪ | C36: Hot-dip galvanized cable tray in ladder and solid-bottom types with bonding jumpers; steel conduit systems concealed in the ceiling void.
B37: ▪ | C37: Copper power cabling in low-smoke halogen-free XLPE from 3x4 mm2 to 4x150+1x70 mm2, with indoor dry-type terminations.
B38: ▪ | C38: Lighting: LED flat panel luminaires surface and recessed, emergency luminaires with battery back-up, directional and exit sign luminaires.
B39: ▪ | C39: Switches, safety receptacles including weatherproof types, junction boxes and all final connections.
B40: ▪ | C40: Earthing and bonding: supplementary equipotential bonding boxes, galvanized flat steel earthing conductors, earthing conductors in conduit, with resistance measurement and certification.
B41: ▪ | C41: Commissioning of the power distribution system below 1 kV and removal of existing electrical installations.
B43: E. PLUMBING, WATER SUPPLY AND DRAINAGE
B44: ▪ | C44: Sanitary fixtures: water closets, sensor-flush urinals, undermount lavatories with mixer faucets and mop sink.
B45: ▪ | C45: Potable water distribution in PP-R from De20 to De40, concealed in ceiling void and chased in wall.
B46: ▪ | C46: Sanitary drainage: internally epoxy-coated galvanized steel main of De110 and PVC branches of De110, De75 and De50, with floor drains and cleanouts.
...

Sheet 4. EXCLUSIONS & ASSUMPTIONS
A1: LESTRAL CONSTRUCTORA, S. DE R.L. DE C.V. | ELECTROMECÁNICA DEL PACÍFICO (EMP)
A2: 4. EXCLUSIONS, ASSUMPTIONS AND BASIS OF PRICE
B4: EXCLUSIONS
B5: 1 | C5: Process and production equipment, and any utility connection downstream of the pre-installed valve or terminal box left by this contract.
B6: 2 | C6: Compressed air branch piping downstream of the eight pre-installed DN20 valves; air compressor, dryer, receiver and treatment train.
B7: 3 | C7: Head-end low-voltage equipment: CCTV server, switches, NVR, access control server and card issuer, all reused from the owner's existing installation.
B8: 4 | C8: Office furniture, workstations, lockers, cabinets, changing room lavatory counters and waste bins, as noted in the client's bill of quantities.
B9: 5 | C9: Deionized, purified or process water generation, storage and distribution.
B10: 6 | C10: Municipal, state and federal permits, licences and rights of way; utility company connection fees and demand charges.
B11: 7 | C11: Electrical service upgrade upstream of the existing main switchboard, including utility transformer, metering and primary feeder.
B12: 8 | C12: Structural reinforcement of the existing building slab, foundations or roof beyond the steelwork shown in the executive project.
B13: 9 | C13: Removal, treatment or disposal of hazardous materials, asbestos or contaminated soil discovered during the works.
B14: 10 | C14: Cleanroom garments, consumables, spare filters beyond the first set installed, and operator training beyond the handover session.
B15: 11 | C15: Third-party certification bodies' fees where the owner elects to appoint an independent certifier.
B16: 12 | C16: Import duties and customs charges on owner-supplied equipment.
B18: ASSUMPTIONS AND BASIS OF PRICE
B19: 1 | C19: All quantities are taken from the client's bill of quantities dated 10-Sep-2026 without re-measurement. Quantities are subject to verification against the IFC drawings during shop drawing production; variations are settled at the unit prices in this quotation.
B20: 2 | C20: Unit prices are firm for 30 calendar days and are expressed in US dollars. Where a reference exchange rate is required for peso-denominated inputs, 17.00 MXN per USD has been used; the rate is reconsidered at contract signature.
B21: 3 | C21: Prices include material, labour, equipment, tools, transport, supervision, site overheads and the contractor's warranty obligations, delivered and installed in place.
B22: 4 | C22: Free, safe and continuous access to the work areas during the agreed working hours, with a clear work front and adequate laydown area inside the plant.
B23: 5 | C23: Existing electrical service has sufficient spare capacity at the main switchboard to serve the new load; this is confirmed by measurement during the first two weeks and reported to the owner.
B24: 6 | C24: The 380 V equipment specified in the executive project is priced as designed, together with the 200 kVA step-down transformer required to serve it.
B25: 7 | C25: The fire protection system is priced as designed to GB codes. Approval by the Mexican authority and by the plant insurer is assumed to be obtained by the owner on that basis, or the NFPA alternative in the Value Engineering section is adopted.
B26: 8 | C26: Building structure, slab and roof are sound and able to receive the new loads without reinforcement other than that shown in the drawings.
B27: 9 | C27: Work is executed on a single day shift, Monday to Saturday. A night-shift and acceleration allowance is carried in the preliminaries and is released if 24-hour access is granted.
B28: 10 | C28: VAT of 8% applies under the Northern Border Region tax incentive for Baja California.
B29: 11 | C29: Changes in scope, quantity or specification are executed against a signed change order at the unit prices herein.

Sheet 5. BOQ DETAIL
A1: LESTRAL CONSTRUCTORA, S. DE R.L. DE C.V. | ELECTROMECÁNICA DEL PACÍFICO (EMP)
A2: 5. PRICED BILL OF QUANTITIES — ALL FIGURES IN USD
A3: EDITABLE CELLS: columns E and F (material and installation unit prices), shown in blue. Everything else is formula-driven and updates automatically.
A5: CODE | B5: DESCRIPTION | C5: UNIT | D5: QTY | E5: MATERIAL U.P. | F5: INSTALL U.P. | G5: TOTAL U.P. | H5: AMOUNT
A6: SECTION A — 01 PRELIMINARIES AND CONSTRUCTION MEASURES
A7: A-001 | B7: Site management: superintendent, safety officer and site administration for the full construction period | C7: LOT | D7: 1 | E7: 0 | F7: 46500 | G7: =E7+F7 -> 46500 | H7: =ROUND(D7*G7,2) -> 46500
A8: A-002 | B8: Temporary site facilities: erection, use and dismantling of site office, storage, changing area and temporary services | C8: LOT | D8: 1 | E8: 0 | F8: 18500 | G8: =E8+F8 -> 18500 | H8: =ROUND(D8*G8,2) -> 18500
A9: A-003 | B9: Site safety and security measures: signage, barriers, PPE, fire watch and access control | C9: LOT | D9: 1 | E9: 0 | F9: 12500 | G9: =E9+F9 -> 12500 | H9: =ROUND(D9*G9,2) -> 12500
A10: A-004 | B10: Unloading, receiving, custody and internal handling of owner-supplied and contractor-supplied equipment and materials | C10: LOT | D10: 1 | E10: 0 | F10: 14000 | G10: =E10+F10 -> 14000 | H10: =ROUND(D10*G10,2) -> 14000
A11: A-005 | B11: Scaffolding and elevated work platforms: erection, dismantling, rental, transport and consumables | C11: LOT | D11: 1 | E11: 0 | F11: 16500 | G11: =E11+F11 -> 16500 | H11: =ROUND(D11*G11,2) -> 16500
A12: A-006 | B12: All temporary utilities consumed during construction (power, water, compressed air) | C12: LOT | D12: 1 | E12: 0 | F12: 9500 | G12: =E12+F12 -> 9500 | H12: =ROUND(D12*G12,2) -> 9500
A13: A-007 | B13: Insurance for personnel and equipment: civil liability, all-risk construction, IMSS and statutory contributions | C13: LOT | D13: 1 | E13: 0 | F13: 14500 | G13: =E13+F13 -> 14500 | H13: =ROUND(D13*G13,2) -> 14500
A14: A-008 | B14: Lifting, hoisting and rigging required for materials and equipment placement | C14: LOT | D14: 1 | E14: 0 | F14: 8500 | G14: =E14+F14 -> 8500 | H14: =ROUND(D14*G14,2) -> 8500
A15: A-009 | B15: Shop drawings, code-compliance adaptation of the IFC package to Mexican standards (NOM-001-SEDE, NOM-002-STPS, NFPA) and as-built drawing production | C15: LOT | D15: 1 | E15: 0 | F15: 26500 | G15: =E15+F15 -> 26500 | H15: =ROUND(D15*G15,2) -> 26500
A16: A-010 | B16: Secondary material handling and internal transport within the plant | C16: LOT | D16: 1 | E16: 0 | F16: 6500 | G16: =E16+F16 -> 6500 | H16: =ROUND(D16*G16,2) -> 6500
A17: A-011 | B17: Project elevations, setting out, layout lines and surveying | C17: LOT | D17: 1 | E17: 0 | F17: 7500 | G17: =E17+F17 -> 7500 | H17: =ROUND(D17*G17,2) -> 7500
A18: A-012 | B18: Daily progress reporting and photographic record | C18: LOT | D18: 1 | E18: 0 | F18: 4800 | G18: =E18+F18 -> 4800 | H18: =ROUND(D18*G18,2) -> 4800
... A28: A-022 | B28: Design drawing sets, transmittals and signature approval records | C28: LOT | D28: 1 | E28: 0 | F28: 4200 | G28: =E28+F28 -> 4200 | H28: =ROUND(D28*G28,2) -> 4200
A29: A TOTAL | B29: SUBTOTAL SECTION A — 01 PRELIMINARIES AND CONSTRUCTION MEASURES | H29: =SUM(H7:H28) -> 266800
A31: SECTION B — 02 ARCHITECTURAL, STRUCTURE AND FINISHES
A32: B-001 | B32: Steel columns, 200x200x6 Q235B equivalent ASTM A36/A572, including base plates, stiffeners, grade-C bolts and anchor bolts, shop primed | C32: TON | D32: 6.386016 | E32: 2350 | F32: 920 | G32: =E32+F32 -> 3270 | H32: =ROUND(D32*G32,2) -> 20882.27
A33: B-002 | B33: Steel beams HM244x175x7x11 and HM294x200x8x12 Q235B equivalent, including connections and shop priming | C33: TON | D33: 21.728 | E33: 2280 | F33: 880 | G33: =E33+F33 -> 3160 | H33: =ROUND(D33*G33,2) -> 68660.48
A34: B-003 | B34: Steel purlins, straight and diagonal tie rods, struts and access ladders: channel, angle, rectangular tube, plate and I-beam | C34: TON | D34: 5.926 | E34: 2420 | F34: 1120 | G34: =E34+F34 -> 3540 | H34: =ROUND(D34*G34,2) -> 20978.04
A35: B-004 | B35: Embedded steel plates and inserts per drawings, including derusting and anti-corrosive primer | C35: TON | D35: 0.994752 | E35: 2650 | F35: 1450 | G35: =E35+F35 -> 4100 | H35: =ROUND(D35*G35,2) -> 4078.48
A36: B-005 | B36: High-strength structural bolts M20, grade 10.9, including washers and torque record | C36: SET | D36: 388 | E36: 4.6 | F36: 3.1 | G36: =E36+F36 -> 7.7 | H36: =ROUND(D36*G36,2) -> 2987.6
A37: B-006 | B37: 200 mm lightweight block wall with cement mortar render, including dowelling, tie bars, bond beam, curb and lintels | C37: M2 | D37: 159.5 | E37: 23.5 | F37: 29.5 | G37: =E37+F37 -> 53 | H37: =ROUND(D37*G37,2) -> 8453.5
A38: B-007 | B38: Restroom wall tile 300x600 mm set with specialty adhesive over 1.5 mm polyurethane waterproofing membrane | C38: M2 | D38: 200.8272 | E38: 27 | F38: 25 | G38: =E38+F38 -> 52 | H38: =ROUND(D38*G38,2) -> 10443.01
A39: B-008 | B39: Cleanroom sandwich panel partition, 50 mm rock wool core, including aluminum profiles and full silicone sealing of joints | C39: M2 | D39: 1127.992 | E39: 118 | F39: 44 | G39: =E39+F39 -> 162 | H39: =ROUND(D39*G39,2) -> 182734.7
A40: B-009 | B40: Wire mesh enclosure fence, 50 mm square tube posts at 2.5 m, mesh wire not less than 2.4 mm, including gate and floor anchoring | C40: LM | D40: 73.2348 | E40: 49 | F40: 23 | G40: =E40+F40 -> 72 | H40: =ROUND(D40*G40,2) -> 5272.91
A41: B-010 | B41: Anti-slip floor tile 600x600 mm set with specialty adhesive over 1.5 mm polyurethane waterproofing membrane | C41: M2 | D41: 61.803 | E41: 28.5 | F41: 23 | G41: =E41+F41 -> 51.5 | H41: =ROUND(D41*G41,2) -> 3182.85
A42: B-011 | B42: Threshold stone including adhesive, substrate preparation, levelling, chamfering and edge polishing | C42: M2 | D42: 1.2 | E42: 68 | F42: 32 | G42: =E42+F42 -> 100 | H42: =ROUND(D42*G42,2) -> 120
A43: B-012 | B43: Electrostatic-dissipative (ESD) epoxy floor system: epoxy primer, epoxy mortar, ESD epoxy mortar, copper foil grid and epoxy topcoat | C43: M2 | D43: 646.3275 | E43: 59 | F43: 39 | G43: =E43+F43 -> 98 | H43: =ROUND(D43*G43,2) -> 63340.1
... A62: B-031 | B62: Demolition and making good: existing restroom walls, floors and ceilings; other partition walls and ceilings; floor repair to match adjacent finish | C62: LOT | D62: 1 | E62: 0 | F62: 29500 | G62: =E62+F62 -> 29500 | H62: =ROUND(D62*G62,2) -> 29500
A63: B TOTAL | B63: SUBTOTAL SECTION B — 02 ARCHITECTURAL, STRUCTURE AND FINISHES | H63: =SUM(H32:H62) -> 606786.77
A65: SECTION C — 03 HVAC AND CLEANROOM AIR SYSTEMS
A66: C-001 | B66: High static pressure fan coil unit, 10.0 kW cooling / 11.2 kW heating, 250 W, 1ph 220V 60Hz, with integral condensate lift pump | C66: SET | D66: 12 | E66: 1180 | F66: 270 | G66: =E66+F66 -> 1450 | H66: =ROUND(D66*G66,2) -> 17400
A67: C-002 | B67: High static pressure fan coil unit, 12.5 kW cooling / 14.0 kW heating, 340 W, 1ph 220V 60Hz, with integral condensate lift pump | C67: SET | D67: 1 | E67: 1420 | F67: 295 | G67: =E67+F67 -> 1715 | H67: =ROUND(D67*G67,2) -> 1715
A68: C-003 | B68: Multi-split indoor unit, 4-way ceiling cassette, 5.6 kW cooling / 6.5 kW heating, 40 W, 1ph 220V 60Hz | C68: SET | D68: 1 | E68: 985 | F68: 225 | G68: =E68+F68 -> 1210 | H68: =ROUND(D68*G68,2) -> 1210
A69: C-004 | B69: Outdoor condensing unit serving the fan coil system, 123.5 kW cooling / 137.5 kW heating, 41.57 kW, 3ph 60Hz, on outdoor housekeeping pad | C69: SET | D69: 1 | E69: 36500 | F69: 4300 | G69: =E69+F69 -> 40800 | H69: =ROUND(D69*G69,2) -> 40800
A70: C-005 | B70: Wall-mounted thermostat with room temperature control | C70: PC | D70: 14 | E70: 148 | F70: 46 | G70: =E70+F70 -> 194 | H70: =ROUND(D70*G70,2) -> 2716
...

Sheet 6. COST SUMMARY
A1: LESTRAL CONSTRUCTORA, S. DE R.L. DE C.V. | ELECTROMECÁNICA DEL PACÍFICO (EMP)
A2: 6. COST SUMMARY — ALL FIGURES IN USD
B4: CONCEPT | C4: RATE | D4: AMOUNT (USD) | E4: BASIS
B5: A. 01 PRELIMINARIES AND CONSTRUCTION MEASURES | D5: =SUMIF('5. BOQ DETAIL'!$A:$A,"A TOTAL",'5. BOQ DETAIL'!$H:$H) -> 266800 | E5: Sum of priced line items, sheet 5
B6: B. 02 ARCHITECTURAL, STRUCTURE AND FINISHES | D6: =SUMIF('5. BOQ DETAIL'!$A:$A,"B TOTAL",'5. BOQ DETAIL'!$H:$H) -> 606786.77 | E6: Sum of priced line items, sheet 5
B7: C. 03 HVAC AND CLEANROOM AIR SYSTEMS | D7: =SUMIF('5. BOQ DETAIL'!$A:$A,"C TOTAL",'5. BOQ DETAIL'!$H:$H) -> 365367 | E7: Sum of priced line items, sheet 5
B8: D. 04 ELECTRICAL INSTALLATIONS | D8: =SUMIF('5. BOQ DETAIL'!$A:$A,"D TOTAL",'5. BOQ DETAIL'!$H:$H) -> 275378.78 | E8: Sum of priced line items, sheet 5
B9: E. 05 PLUMBING, WATER SUPPLY AND DRAINAGE | D9: =SUMIF('5. BOQ DETAIL'!$A:$A,"E TOTAL",'5. BOQ DETAIL'!$H:$H) -> 62252.99 | E9: Sum of priced line items, sheet 5
B10: F. 06 FIRE PROTECTION AND FIRE ALARM | D10: =SUMIF('5. BOQ DETAIL'!$A:$A,"F TOTAL",'5. BOQ DETAIL'!$H:$H) -> 150728.24 | E10: Sum of priced line items, sheet 5
B11: G. 07 IT, CCTV AND ACCESS CONTROL | D11: =SUMIF('5. BOQ DETAIL'!$A:$A,"G TOTAL",'5. BOQ DETAIL'!$H:$H) -> 34987.99 | E11: Sum of priced line items, sheet 5
B12: H. 08 COMPRESSED AIR DISTRIBUTION | D12: =SUMIF('5. BOQ DETAIL'!$A:$A,"H TOTAL",'5. BOQ DETAIL'!$H:$H) -> 30317.09 | E12: Sum of priced line items, sheet 5
B13: A. TOTAL DIRECT COST | D13: =SUM(D5:D12) -> 1792618.9 | E13: Material plus installation, all 341 line items, delivered and installed in place
B14: B. INDIRECT COST (head office overhead, bonds, financing) | C14: 0.08 | D14: =ROUND(D13*C14,2) -> 143409.51 | E14: 8% on direct cost. Site overheads (supervision, insurance, temporary facilities, utilities) are already priced in Section A, so this rate covers head office only and avoids double counting.
B15: C. SUBTOTAL (direct + indirect) | D15: =D13+D14 -> 1936028.4
B16: D. CONTRACTOR'S PROFIT | C16: 0.1 | D16: =ROUND(D15*C16,2) -> 193602.84 | E16: 10% on the subtotal above, standard for turnkey industrial work of this scale in Baja California.
B17: E. SUBTOTAL (direct + indirect + profit) | D17: =D15+D16 -> 2129631.2
B18: F. CONTINGENCY | C18: 0.03 | D18: =ROUND(D17*C18,2) -> 63888.94 | E18: 3% on the subtotal above. Covers quantity variation on verification against the IFC drawings and minor unforeseen conditions in the existing building. Unused contingency is returned to the client at final account.
B19: G. TOTAL BEFORE VAT | D19: =D17+D18 -> 2193520.1 | E19: Contract price excluding tax
B20: H. VAT | C20: 0.08 | D20: =ROUND(D19*C20,2) -> 175481.61 | E20: 8% under the Northern Border Region tax incentive for Baja California
B21: I. TOTAL CONTRACT PRICE (VAT included) | D21: =D19+D20 -> 2369001.8
B23: MATERIAL / INSTALLATION SPLIT
B24: Material and equipment procurement | D24: =SUMPRODUCT('5. BOQ DETAIL'!$D$6:$D$371,'5. BOQ DETAIL'!$E$6:$E$371) -> 963504.39 | E24: Column D x column E, sheet 5
B25: Construction and installation works | D25: =SUMPRODUCT('5. BOQ DETAIL'!$D$6:$D$371,'5. BOQ DETAIL'!$F$6:$F$371) -> 829114.48 | E25: Column D x column F, sheet 5

Sheet 7. COMMERCIAL TERMS
A1: LESTRAL CONSTRUCTORA, S. DE R.L. DE C.V. | ELECTROMECÁNICA DEL PACÍFICO (EMP)
A2: 7. COMMERCIAL TERMS AND CONDITIONS
B4: 7.1 PAYMENT SCHEDULE
B5: MILESTONE | C5: % OF PRICE | D5: AMOUNT (USD) | E5: RELEASE CONDITION
B6: Advance payment on contract signature (week 1) | C6: 0.3 | D6: =ROUND('6. COST SUMMARY'!$D$21*C6,2) -> 710700.53 | E6: Signed contract or purchase order, invoice and advance payment bond if required
B7: Progress estimate 1 - structure and partitions (week 7) | C7: 0.2 | D7: =ROUND('6. COST SUMMARY'!$D$21*C7,2) -> 473800.35 | E7: Certified progress, invoice and photographic report
B8: Progress estimate 2 - MEP rough-in complete (week 13) | C8: 0.25 | D8: =ROUND('6. COST SUMMARY'!$D$21*C8,2) -> 592250.44 | E8: Certified progress, invoice and rough-in inspection sign-off
B9: Progress estimate 3 - finishes and equipment set (week 18) | C9: 0.15 | D9: =ROUND('6. COST SUMMARY'!$D$21*C9,2) -> 355350.26 | E9: Certified progress, invoice and test reports
B10: Final payment on handover and acceptance (week 24) | C10: 0.1 | D10: =ROUND('6. COST SUMMARY'!$D$21*C10,2) -> 236900.18 | E10: Handover certificate, close-out dossier and invoice
B11: TOTAL | C11: =SUM(C6:C10) -> 1 | D11: =SUM(D6:D10) -> 2369001.8
B13: 7.2 OFFER VALIDITY AND CURRENCY
B14: • Validity: 30 calendar days from 10 September 2026. After that date prices are subject to review against supplier quotations then current.
B15: • Currency: US dollars (USD). All payments are made in USD. Where a reference exchange rate is needed for peso inputs, 17.00 MXN/USD has been used and is reconsidered at contract signature.
B16: • Prices are unit prices, firm for the validity period, and include material, labour, equipment, tools, transport, supervision and site overheads, delivered and installed in place.
B17: • VAT of 8% applies under the Northern Border Region tax incentive for Baja California and is shown separately in the cost summary.
B19: 7.3 ADVANCE PAYMENT AND ESTIMATES
B20: • Advance payment: 30% of the contract price on signature, against invoice and, if required by the client, an advance payment bond issued by a Mexican surety.
B21: • The advance is amortized proportionally against each subsequent progress estimate.
B22: • Progress estimates are submitted monthly, certified jointly by the client's representative and EMP's superintendent, supported by measured quantities and a photographic report.
B23: • Payment term: 7 business days from acceptance of the certified estimate and receipt of a valid invoice. Final payment: 10 business days.
B24: • Retention: 5% of each estimate may be retained by the client and is released against the handover certificate, or may be substituted by a performance bond of equivalent value.
B26: 7.4 WARRANTIES
... B49: Lestral Constructora / Electromecánica del Pacífico (EMP) — Technical lead and single point of contact

Sheet 8. SCHEDULE GANTT
A1: LESTRAL CONSTRUCTORA, S. DE R.L. DE C.V. | ELECTROMECÁNICA DEL PACÍFICO (EMP)
A2: 8. CONSTRUCTION PROGRAMME — WEEKLY GANTT WITH CRITICAL PATH AND MILESTONES
B4: Duration 24 weeks from advance payment. Legend: ■ critical path ■ non-critical activity ◆ milestone ▲ payment milestone
B6: # | C6: ACTIVITY | D6: PATH | E6: 1 | F6: 2 | G6: 3 | H6: 4 | I6: 5 | J6: 6 | K6: 7 | L6: 8 | M6: 9 | N6: 10 | O6: 11 | P6: 12 | Q6: 13 | R6: 14 | S6: 15 | T6: 16 | U6: 17 | V6: 18 | W6: 19 | X6: 20 | Y6: 21 | Z6: 22 | AA6: 23 | AB6: 24
B7: 1 | C7: Contract award, mobilization and submittals | D7: CP
B8: 2 | C8: Long-lead equipment procurement (VRF, DX AHU, boards, transformer) | D8: CP
B9: 3 | C9: Shop drawings and NOM code-compliance adaptation | D9: CP
B10: 4 | C10: Demolition and removal of existing MEP | D10: CP
B11: 5 | C11: Wall and floor chasing, core drilling | D11: —
B12: 6 | C12: Steel structure shop fabrication | D12: —
B13: 7 | C13: Steel structure erection | D13: CP
B14: 8 | C14: Block walls and masonry | D14: —
B15: 9 | C15: HVAC ductwork rough-in | D15: CP
B16: 10 | C16: Refrigerant and condensate piping | D16: —
B17: 11 | C17: Electrical tray, conduit and wiring rough-in | D17: —
B18: 12 | C18: Sprinkler and hydrant piping | D18: —
... B32: 26 | C32: Punch list, final cleaning, as-builts and handover | D32: CP
B34: PROJECT MILESTONES
B35: M1 Contract award and advance payment | E35: ◆
B36: M2 Shop drawings approved | H36: ◆
B37: M3 Structure and partitions complete | R37: ◆
B38: M4 MEP rough-in complete | T38: ◆
B39: M5 Energization and equipment start-up | W39: ◆
B40: M6 Commissioning complete | Y40: ◆
B41: M7 Substantial completion and handover | AB41: ◆
B43: PAYMENT MILESTONES
B44: Advance payment on contract signature (30%) | E44: ▲
B45: Progress estimate 1 - structure and partitions (20%) | K45: ▲
B46: Progress estimate 2 - MEP rough-in complete (25%) | Q46: ▲
B47: Progress estimate 3 - finishes and equipment set (15%) | V47: ▲
B48: Final payment on handover and acceptance (10%) | AB48: ▲
B50: Critical path: contract award and mobilization → long-lead equipment procurement → shop drawings and NOM adaptation → demolition → steel erection → HVAC ductwork rough-in → cleanroom wall panel → cleanroom ceiling panel → HVAC equipment set → epoxy flooring → commissioning and balancing → cleanroom qualification → handover. Procurement of the 123.5 kW condensing unit, the DX air handling unit and the 200 kVA transformer governs the first ten weeks; the Value Engineering measures in sheet 9 remove the transformer and the imported commodity materials from that critical path.

Sheet 9. VALUE ENGINEERING
A1: LESTRAL CONSTRUCTORA, S. DE R.L. DE C.V. | ELECTROMECÁNICA DEL PACÍFICO (EMP)
A2: 9. VALUE ENGINEERING PROPOSED BY EMP
B4: The base quotation prices the executive project exactly as designed. The alternatives below are EMP's proposals; none has been applied to the base price. Each is quantified separately so the client can accept or reject it on its own merits. Savings are calculated on the affected line items in sheet 5.
B7: 9.1 COST REDUCTION ALTERNATIVES
B8: REF | C8: ALTERNATIVE | D8: SCHEDULE IMPACT | E8: ESTIMATED SAVING (USD) | F8: PERFORMANCE IMPACT
B9: VE-01 | C9: Re-specify all equipment and boards at 480/277-220 V, 60 Hz (NEMA/NOM) and delete the 200 kVA 480/380 V transformer | D9: -2 weeks | E9: 15400 | F9: Native NOM-001-SEDE compliance; removes ~2% transformation loss and a single point of failure; spare parts available locally instead of imported
B10: VE-02 | C10: Substitute GB-standard raceway, conductor and water pipe for North American equivalents (JDG/SC to EMT/RMC, GB cable to THHN/XHHW, PP-R to CPVC) | D10: -4 weeks | E10: 13287.63 | F10: Equal or better performance, UL listed and NOM certified; removes 8-12 week import lead time and customs exposure on commodity materials
B11: VE-03 | C11: Convert the GB fire design to NFPA 13 / NFPA 14 hydraulic design with K5.6 heads and a single combined riser serving sprinklers and hose stations | D11: -1 weeks | E11: 13295.04 | F11: Insurable design (FM/NFPA) accepted by Mexican authority and by the plant insurer; removes the re-inspection and re-work risk of a GB-only submittal
B12: VE-04 | C12: Limit walkable cleanroom sandwich ceiling to classified areas; standard suspended ceiling in offices, change room and support areas | D12: -1 weeks | E12: 20302.49 | F12: No effect on ISO classification: the affected areas are outside the classified envelope and carry no pressure cascade requirement
B13: VE-05 | C13: Apply ESD epoxy only to the areas with a declared electrostatic requirement; standard epoxy elsewhere | D13: neutral | E13: 6948.02 | F13: Requires written confirmation of the ESD zone boundary by the owner; ESD performance is unchanged inside the declared zone
B14: VE-06 | C14: Use pre-insulated phenolic panel duct for the non-classified outside air and exhaust runs instead of galvanized duct with external insulation | D14: -1 weeks | E14: 2136.42 | F14: Lower leakage class and better thermal performance; fabricated on site, which removes the sheet-metal shop queue from the critical path
B15: VE-07 | C15: Release the night-shift and acceleration allowance in exchange for 24-hour site access and a clear work front | D15: neutral | E15: 9500 | F15: Requires the owner to grant unrestricted access; if access remains restricted to a single shift, the allowance must be reinstated
B16: Σ | C16: TOTAL DIRECT-COST SAVING IDENTIFIED | D16: -4 weeks | E16: =SUM(E9:E15) -> 80869.6
B18: 9.2 PERFORMANCE ALTERNATIVES (additional capital cost, operating cost reduction)
B19: REF | C19: ALTERNATIVE | D19: ADDED CAPEX (USD) | E19: ANNUAL OPEX SAVING (USD) | F19: PERFORMANCE IMPACT
B20: VE-08 | C20: Heat-recovery VRF bank in place of two independent condensing units | D20: 11500 | E20: 8600 | F20: Transfers heat between zones that call for cooling and heating simultaneously; payback approx. 1.3 years
B21: VE-09 | C21: Enthalpy recovery wheel on the 2,500 m3/h outside air unit | D21: 6800 | E21: 5400 | F21: Recovers approx. 65% of the outside air enthalpy load; payback approx. 1.3 years and reduces peak demand
B22: VE-10 | C22: 0-10 V dimming and occupancy control on non-classified area lighting | D22: 0 | E22: 3200 | F22: No capital cost impact when specified at purchase; reduces lighting energy by approx. 35% in intermittently occupied areas
B23: Σ | C23: TOTAL | D23: =SUM(D20:D22) -> 18300 | E23: =SUM(E20:E22) -> 17200
B25: EMP's recommendation: VE-01, VE-02 and VE-03 should be treated as compliance items rather than optional savings. The 380 V distribution voltage does not exist in the Mexican grid, and the GB fire design is not the basis on which the local authority or the plant insurer will approve the installation. Adopting the three together removes the transformer, the imported commodity materials and the re-submittal risk from the critical path, and is the single largest contributor to both the cost and the schedule reduction shown in sheet 10.

Sheet 10. BASE VS OPTIMIZED
A1: LESTRAL CONSTRUCTORA, S. DE R.L. DE C.V. | ELECTROMECÁNICA DEL PACÍFICO (EMP)
A2: 10. SCENARIO COMPARISON — BASE CASE VS OPTIMIZED CASE
B4: Base case: the executive project priced exactly as designed. Optimized case: the base case with all seven cost-reduction alternatives of sheet 9.1 adopted.
B6: CONCEPT | C6: BASE CASE | D6: OPTIMIZED CASE | E6: DIFFERENCE
B7: Direct cost | C7: ='6. COST SUMMARY'!D13 -> 1792618.9 | D7: =C7-'9. VALUE ENGINEERING'!E16 -> 1711749.3 | E7: =D7-C7 -> -80869.6
B8: Indirect cost (8%) | C8: =ROUND(C7*'6. COST SUMMARY'!C14,2) -> 143409.51 | D8: =ROUND(D7*'6. COST SUMMARY'!C14,2) -> 136939.94 | E8: =D8-C8 -> -6469.57
B9: Profit (10%) | C9: =ROUND((C7+C8)*'6. COST SUMMARY'!C16,2) -> 193602.84 | D9: =ROUND((D7+D8)*'6. COST SUMMARY'!C16,2) -> 184868.92 | E9: =D9-C9 -> -8733.92
B10: Contingency (3%) | C10: =ROUND((C7+C8+C9)*'6. COST SUMMARY'!C18,2) -> 63888.94 | D10: =ROUND((D7+D8+D9)*'6. COST SUMMARY'!C18,2) -> 61006.74 | E10: =D10-C10 -> -2882.2
B11: TOTAL BEFORE VAT | C11: =C7+C8+C9+C10 -> 2193520.1 | D11: =D7+D8+D9+D10 -> 2094564.9 | E11: =D11-C11 -> -98955.29
B12: VAT 8% | C12: =ROUND(C11*'6. COST SUMMARY'!C20,2) -> 175481.61 | D12: =ROUND(D11*'6. COST SUMMARY'!C20,2) -> 167565.19 | E12: =D12-C12 -> -7916.42
B13: TOTAL CONTRACT PRICE | C13: =C11+C12 -> 2369001.8 | D13: =D11+D12 -> 2262130 | E13: =D13-C13 -> -106871.71
B14: Saving as % of contract price | C14: 0 | D14: =-E13/C13 -> 0.04511255 | E14: =D14 -> 0.04511255
B15: Construction duration (weeks) | C15: 24 | D15: 20 | E15: -4
B16: Annual operating cost saving (if 9.2 adopted) | C16: 0 | D16: ='9. VALUE ENGINEERING'!E23 -> 17200 | E16: =D16 -> 17200
B18: BENEFITS OF THE OPTIMIZED CASE
B19: • Equipment operates at a distribution voltage that exists in Mexico, so spare parts, service and future extensions are sourced locally instead of imported.
B20: • The 200 kVA transformer disappears from the electrical room, together with its standing losses, its footprint and its 10 to 12 week lead time.
B21: • Commodity materials (conduit, conductor, water pipe) become UL listed and NOM certified, removing the customs and lead-time exposure from the critical path.
B22: • The fire protection system becomes insurable on an NFPA basis, which is what both the Mexican authority and the plant insurer will actually review.
B23: • Four weeks are recovered on the critical path, which brings production start-up forward by approximately one month.
B24: • Cleanroom classification, pressure cascade, air change rate and ESD performance inside the declared zone are unchanged in every respect.

Sheet 11. CLIENT BOQ FORMAT
A1: LESTRAL CONSTRUCTORA, S. DE R.L. DE C.V. | ELECTROMECÁNICA DEL PACÍFICO (EMP)
A2: 11. COST SUMMARY MAPPED TO THE CLIENT'S BOQ FORMAT (sheet 01.Summary)
B4: The same price, presented in the client's own summary structure so the two documents can be reconciled line for line.
B6: No. | C6: ITEM DESCRIPTION | D6: CONSTRUCTION AND INSTALLATION (USD) | E6: EQUIPMENT PROCUREMENT (USD) | F6: TOTAL COST (USD)
B7: 1 | C7: Construction measures cost | D7: =SUMPRODUCT('5. BOQ DETAIL'!$D$7:$D$28,'5. BOQ DETAIL'!$F$7:$F$28) -> 266800 | E7: =SUMPRODUCT('5. BOQ DETAIL'!$D$7:$D$28,'5. BOQ DETAIL'!$E$7:$E$28) -> 0 | F7: =D7+E7 -> 266800
B8: 2 | C8: Building decoration | D8: =SUMPRODUCT('5. BOQ DETAIL'!$D$32:$D$62,'5. BOQ DETAIL'!$F$32:$F$62) -> 198570.57 | E8: =SUMPRODUCT('5. BOQ DETAIL'!$D$32:$D$62,'5. BOQ DETAIL'!$E$32:$E$62) -> 408216.21 | F8: =D8+E8 -> 606786.78
B9: 3 | C9: HVAC works | D9: =SUMPRODUCT('5. BOQ DETAIL'!$D$66:$D$176,'5. BOQ DETAIL'!$F$66:$F$176) -> 121764.52 | E9: =SUMPRODUCT('5. BOQ DETAIL'!$D$66:$D$176,'5. BOQ DETAIL'!$E$66:$E$176) -> 243602.47 | F9: =D9+E9 -> 365366.99
B10: 4 | C10: Water supply and drainage works | D10: =SUMPRODUCT('5. BOQ DETAIL'!$D$246:$D$280,'5. BOQ DETAIL'!$F$246:$F$280) -> 26629.037 | E10: =SUMPRODUCT('5. BOQ DETAIL'!$D$246:$D$280,'5. BOQ DETAIL'!$E$246:$E$280) -> 35623.958 | F10: =D10+E10 -> 62252.995
B11: 5 | C11: Fire protection works | D11: =SUMPRODUCT('5. BOQ DETAIL'!$D$284:$D$334,'5. BOQ DETAIL'!$F$284:$F$334) -> 74581.988 | E11: =SUMPRODUCT('5. BOQ DETAIL'!$D$284:$D$334,'5. BOQ DETAIL'!$E$284:$E$334) -> 76146.258 | F11: =D11+E11 -> 150728.25
B12: 6 | C12: Electrical works | D12: =SUMPRODUCT('5. BOQ DETAIL'!$D$180:$D$242,'5. BOQ DETAIL'!$F$180:$F$242) -> 112676.91 | E12: =SUMPRODUCT('5. BOQ DETAIL'!$D$180:$D$242,'5. BOQ DETAIL'!$E$180:$E$242) -> 162701.87 | F12: =D12+E12 -> 275378.79
B13: 7 | C13: Low-voltage works | D13: =SUMPRODUCT('5. BOQ DETAIL'!$D$338:$D$357,'5. BOQ DETAIL'!$F$338:$F$357) -> 17064.51 | E13: =SUMPRODUCT('5. BOQ DETAIL'!$D$338:$D$357,'5. BOQ DETAIL'!$E$338:$E$357) -> 17923.479 | F13: =D13+E13 -> 34987.988
B14: 8 | C14: Compressed air works | D14: =SUMPRODUCT('5. BOQ DETAIL'!$D$361:$D$368,'5. BOQ DETAIL'!$F$361:$F$368) -> 11026.943 | E14: =SUMPRODUCT('5. BOQ DETAIL'!$D$361:$D$368,'5. BOQ DETAIL'!$E$361:$E$368) -> 19290.147 | F14: =D14+E14 -> 30317.09
B15: 9 | C15: Shipping | D15: 0 | E15: 0 | F15: Included in the unit prices; no separate imported freight is carried
B16: 10 | C16: Customs declaration and clearance fees | D16: 0 | E16: 0 | F16: Not applicable: materials are procured domestically
B17: 11 | C17: Project management fee | D17: ='6. COST SUMMARY'!D14+'6. COST SUMMARY'!D16+'6. COST SUMMARY'!D18 -> 400901.29 | E17: 0 | F17: =D17+E17 -> 400901.29
B18: 12 | C18: Subtotal excluding VAT | D18: =SUM(D7:D17) -> 1230015.8 | E18: =SUM(E7:E17) -> 963504.39 | F18: =D18+E18 -> 2193520.2
B19: 13 | C19: VAT 8% | F19: =ROUND(F18*'6. COST SUMMARY'!C20,2) -> 175481.61
B20: 14 | C20: TOTAL PRICE (USD) | F20: =F18+F19 -> 2369001.8
B22: Line 11 carries the indirect cost, profit and contingency of sheet 6 grouped as a project management fee, which is the closest equivalent in the client's template. The total in line 14 is identical to the total contract price in sheet 6.
