Workbook

Sheet 1. PORTADA
B2: LESTRAL CONSTRUCTORA Electromecánica del Pacífico (EMP)
B5: PROYECTOS INDUSTRIALES LLAVE EN MANO • INGENIERÍA + CONSTRUCCIÓN + INSTALACIÓN
B7: PROPUESTA DE CONSTRUCCIÓN LLAVE EN MANO REMODELACIÓN DE NAVE CON CUARTO LIMPIO
B9: Proyecto de Remodelación de Nave QMX México • Baja California, México
B11: CLIENTE | C11: QMX / QIUSHI
B12: PROYECTO | C12: Proyecto de Remodelación de Nave con Cuarto Limpio, México
B13: SITIO | C13: Baja California, México
B14: BASE DE LA COTIZACIÓN | C14: Proyecto ejecutivo y catálogo de cantidades del 10-sep-2026 (paquete IFC de Shanghai Jingdian)
B15: No. DE COTIZACIÓN | C15: EMP-QMX-2026-09-CR • Rev. D
B16: FECHA | C16: 10 de septiembre de 2026
B17: VIGENCIA | C17: 30 días naturales
B18: MONEDA | C18: Dólares americanos (USD)
B19: PLAZO DE EJECUCIÓN | C19: 24 semanas a partir del anticipo
B20: PRESENTA | C20: ING. RODRIGO NUÑEZ LOUBET
B22: PRECIO TOTAL DE CONSTRUCCIÓN LLAVE EN MANO (IVA INCLUIDO)
B23: ='6. RESUMEN DE COSTOS'!D21 -> 2369001.8
B25: PROPUESTA CONFIDENCIAL • Elaborada exclusivamente para QMX • Blvd. Insurgentes, Tijuana, Baja California, México Un solo punto de responsabilidad • Ingeniería, procura, construcción y puesta en servicio bajo un mismo contrato Este documento sustituye a la propuesta EMP-QMX-2026-08-F1 Rev. C.1 en el alcance cubierto por el proyecto ejecutivo del 10-sep-2026.

Sheet 2. RESUMEN EJECUTIVO
A1: LESTRAL CONSTRUCTORA, S. DE R.L. DE C.V. | ELECTROMECÁNICA DEL PACÍFICO (EMP)
A2: 2. RESUMEN EJECUTIVO
B4: Lestral Constructora / Electromecánica del Pacífico (EMP) presenta esta propuesta de construcción llave en mano para la remodelación de la nave QMX en Baja California, México, que comprende un ambiente controlado de clase ISO junto con sus áreas de apoyo de producción, inspección, vestidor, transferencia y oficinas. La propuesta fue cotizada partida por partida contra el proyecto ejecutivo emitido el 10 de septiembre de 2026 por Shanghai Jingdian Planning & Architectural Design: planos de arquitectura, estructura, HVAC, hidrosanitario, eléctrico, protección contra incendio y aire comprimido, junto con el catálogo de cantidades del mismo paquete. Todas las cantidades de esta cotización se toman directamente de ese catálogo, unidad por unidad, de manera que la oferta pueda compararse contra el documento del propio cliente sin necesidad de recuantificar. El alcance cubre ocho disciplinas y 341 partidas cotizadas: preliminares y medidas de construcción; arquitectónico, estructura metálica y acabados; HVAC y sistemas de aire de cuarto limpio; instalaciones eléctricas; hidráulica, agua potable y drenaje; protección contra incendio y alarma; sistemas de TI, CCTV y control de acceso; y distribución de aire comprimido. EMP actúa como un solo punto de responsabilidad para la adecuación de ingeniería, la procura, la construcción, las pruebas y la puesta en servicio. Dos asuntos requieren la atención del cliente y se desarrollan en la sección de Ingeniería de Valor. Primero, el diseño especifica equipos a 380 V trifásicos, que no es una tensión de distribución disponible en México; el catálogo lo resuelve con un transformador reductor de 200 kVA, pero reespecificar los equipos a 480/277-220 V elimina por completo el transformador. Segundo, el diseño de protección contra incendio sigue normas chinas GB; tanto la aprobación de la autoridad mexicana como el seguro de planta trabajan con NFPA. EMP cotizó el proyecto exactamente como está diseñado y cuantificó ambas alternativas por separado para que el cliente decida con elementos.
B20: COSTO POR DISCIPLINA
B21: DISCIPLINA | C21: PARTIDAS | D21: COSTO DIRECTO (USD) | E21: % DEL DIRECTO
B22: 01 PRELIMINARES Y MEDIDAS DE CONSTRUCCIÓN | C22: 22 | D22: =SUMIF('5. DESGLOSE PARTIDAS'!$A:$A,"A TOTAL",'5. DESGLOSE PARTIDAS'!$H:$H) -> 266800 | E22: =IF($D$30=0,0,D22/$D$30) -> 0.14883253
B23: 02 ARQUITECTÓNICO, ESTRUCTURA Y ACABADOS | C23: 31 | D23: =SUMIF('5. DESGLOSE PARTIDAS'!$A:$A,"B TOTAL",'5. DESGLOSE PARTIDAS'!$H:$H) -> 606786.77 | E23: =IF($D$30=0,0,D23/$D$30) -> 0.33849179
B24: 03 HVAC Y SISTEMAS DE AIRE DE CUARTO LIMPIO | C24: 111 | D24: =SUMIF('5. DESGLOSE PARTIDAS'!$A:$A,"C TOTAL",'5. DESGLOSE PARTIDAS'!$H:$H) -> 365367 | E24: =IF($D$30=0,0,D24/$D$30) -> 0.20381745
B25: 04 INSTALACIONES ELÉCTRICAS | C25: 63 | D25: =SUMIF('5. DESGLOSE PARTIDAS'!$A:$A,"D TOTAL",'5. DESGLOSE PARTIDAS'!$H:$H) -> 275378.78 | E25: =IF($D$30=0,0,D25/$D$30) -> 0.15361814
B26: 05 HIDRÁULICA, AGUA POTABLE Y DRENAJE | C26: 35 | D26: =SUMIF('5. DESGLOSE PARTIDAS'!$A:$A,"E TOTAL",'5. DESGLOSE PARTIDAS'!$H:$H) -> 62252.99 | E26: =IF($D$30=0,0,D26/$D$30) -> 0.034727399
B27: 06 PROTECCIÓN CONTRA INCENDIO Y ALARMA | C27: 51 | D27: =SUMIF('5. DESGLOSE PARTIDAS'!$A:$A,"F TOTAL",'5. DESGLOSE PARTIDAS'!$H:$H) -> 150728.24 | E27: =IF($D$30=0,0,D27/$D$30) -> 0.084082703
B28: 07 SISTEMAS DE TI, CCTV Y CONTROL DE ACCESO | C28: 20 | D28: =SUMIF('5. DESGLOSE PARTIDAS'!$A:$A,"G TOTAL",'5. DESGLOSE PARTIDAS'!$H:$H) -> 34987.99 | E28: =IF($D$30=0,0,D28/$D$30) -> 0.019517808
B29: 08 DISTRIBUCIÓN DE AIRE COMPRIMIDO | C29: 8 | D29: =SUMIF('5. DESGLOSE PARTIDAS'!$A:$A,"H TOTAL",'5. DESGLOSE PARTIDAS'!$H:$H) -> 30317.09 | E29: =IF($D$30=0,0,D29/$D$30) -> 0.016912178
B30: COSTO DIRECTO TOTAL | C30: =SUM(C22:C29) -> 341 | D30: =SUM(D22:D29) -> 1792618.9 | E30: 1
B32: Precio total antes de IVA | C32: ='6. RESUMEN DE COSTOS'!D19 -> 2193520.1
B33: Precio total con IVA 8% | C33: ='6. RESUMEN DE COSTOS'!D21 -> 2369001.8
B34: Plazo de ejecución (semanas) | C34: 24
B35: Ahorro identificado por ingeniería de valor | C35: ='9. INGENIERIA DE VALOR'!E16 -> 80869.6
B36: Plazo optimizado (semanas) | C36: 20

Sheet 3. ALCANCE DEL TRABAJO
A1: LESTRAL CONSTRUCTORA, S. DE R.L. DE C.V. | ELECTROMECÁNICA DEL PACÍFICO (EMP)
A2: 3. ALCANCE DEL TRABAJO DETALLADO POR SISTEMA Y DISCIPLINA
B4: El alcance siguiente es la descripción contractual de los trabajos. Corresponde partida por partida al catálogo cotizado de la hoja 5 y al proyecto ejecutivo emitido el 10-sep-2026.
B6: A. PRELIMINARES Y MEDIDAS DE CONSTRUCCIÓN
B7: ▪ | C7: Administración de obra, superintendencia, coordinación de seguridad y administración de campo durante todo el plazo.
B8: ▪ | C8: Instalaciones provisionales, andamios, maniobras de izaje, servicios temporales, herramienta menor y limpieza de obra.
B9: ▪ | C9: Planos de taller, adecuación del paquete IFC a normativa mexicana (NOM-001-SEDE-2012, NOM-002-STPS-2010, referencias NFPA) y elaboración de planos as-built.
B10: ▪ | C10: Trazo, niveles y levantamiento; muestras, prototipos y pruebas de laboratorio; supervisión de calidad bajo plan de inspección y pruebas.
B11: ▪ | C11: Seguros y cuotas obligatorias, protección de obra terminada, reporte diario de avance con registro fotográfico.
B12: ▪ | C12: Pruebas de calidad de aire interior a la terminación y pruebas, verificación y visto bueno de protección contra incendio ante autoridad.
B14: B. ARQUITECTÓNICO, ESTRUCTURA Y ACABADOS
B15: ▪ | C15: Estructura metálica: columnas, vigas, largueros, tensores, puntales, escaleras, placas ahogadas y tornillería de alta resistencia, con primario de taller y montaje.
B16: ▪ | C16: Envolvente de cuarto limpio en panel sándwich de lana mineral de 50 mm con perfilería de aluminio y juntas totalmente selladas, incluye plafón transitable.
B17: ▪ | C17: Muros de block ligero con repellado, anclaje, refuerzo, dalas y dinteles; malla de cerramiento.
B18: ▪ | C18: Pisos: sistema epóxico disipativo con retícula de cobre sobre mortero epóxico, epóxico bicomponente estándar, loseta antiderrapante sobre impermeabilizante de poliuretano.
B19: ▪ | C19: Puertas de cuarto limpio (dos hojas, una hoja y corrediza) con herrajes completos; ventanas de observación en cristal templado; puertas de baño en chapa de madera.
B20: ▪ | C20: Acabado de baños: azulejo en muro y piso, plafón de aluminio, cubierta de lavabo en mármol, espejo con marco, mamparas, barras de apoyo y accesorios.
B21: ▪ | C21: Demolición de baños, muros divisorios y plafones existentes, con reparación de piso igualando el acabado contiguo.
B23: C. HVAC Y SISTEMAS DE AIRE DE CUARTO LIMPIO
B24: ▪ | C24: Aire acondicionado de cuarto limpio: fan coils de alta presión estática alimentados por una unidad condensadora exterior de 123.5 kW, con termostatos, distribuidores refnet y distribución completa de refrigerante.
B25: ▪ | C25: Aire exterior de cuarto limpio: unidad manejadora de expansión directa de 2,500 m3/h a 300 Pa de presión estática externa con su sección condensadora exterior, compuertas motorizadas y manuales, y manómetros diferenciales para la cascada de presión.
B26: ▪ | C26: Climatización de áreas no clasificadas: unidades interiores multi-split tipo cassette de cuatro vías alimentadas por una condensadora de 33.5 kW, y recuperador de calor total para aire exterior.
B27: ▪ | C27: Ventilación y extracción: ventiladores centrífugos en línea y tipo gabinete, extractores de baño, unidad de filtración de carbón activado para extracción de proceso, celosías a prueba de lluvia y sombreretes.
B28: ▪ | C28: Ducto de lámina galvanizada fabricado e instalado con clase de hermeticidad conforme a GB 50243-2016 / equivalente SMACNA, con aislamiento elastomérico clase B1 y conexiones flexibles de lona.
B29: ▪ | C29: Columnas de retorno, soportería, drenaje de condensados en UPVC, carga adicional de refrigerante y todos los accesorios de tubería.
B30: ▪ | C30: Sistema de control automático del HVAC de cuarto limpio: controladores, sensores de campo, cableado, programación y puesta en marcha.
B31: ▪ | C31: Pruebas, ajuste y balanceo de todos los sistemas de aire, con resultados documentados por zona.
B33: D. INSTALACIONES ELÉCTRICAS
B34: ▪ | C34: Transformador seco tipo interior de 200 kVA, primario 480 V / secundario 380 V, con base y conexiones, según proyecto ejecutivo.
B35: ▪ | C35: Ocho tableros de distribución (1APZ, 1AL1, 1AP-KT, 2AC-KT1, 2AC-KT2, 1AC-PW1, 1AC-PW2, 1ALED) según diagrama unifilar, con interruptores y conexiones, más la adecuación de tableros existentes afectados por el nuevo layout.
B36: ▪ | C36: Charola galvanizada por inmersión en caliente tipo escalera y tipo canal con puentes de continuidad; sistemas de tubería conduit de acero ocultos en plenum de plafón.
B37: ▪ | C37: Cableado de fuerza en cobre con aislamiento XLPE libre de halógenos, desde 3x4 mm2 hasta 4x150+1x70 mm2, con terminales tipo seco interior.
B38: ▪ | C38: Alumbrado: luminarios LED tipo panel plano sobreponer y empotrados, luminarios de emergencia con respaldo de batería, señales luminosas direccionales y de salida.
B39: ▪ | C39: Apagadores, contactos de seguridad incluyendo tipo intemperie, cajas de conexión y todas las conexiones finales.
B40: ▪ | C40: Puesta a tierra y equipotencialidad: cajas de equipotencialidad suplementaria, solera galvanizada, conductores de tierra en tubo, con medición de resistencia y certificación.
B41: ▪ | C41: Puesta en servicio del sistema de distribución menor a 1 kV y desmantelamiento de instalaciones eléctricas existentes.
B43: E. HIDRÁULICA, AGUA POTABLE Y DRENAJE
B44: ▪ | C44: Muebles sanitarios: inodoros, mingitorios con fluxómetro de sensor, lavabos bajo cubierta con mezcladora y vertedero de aseo.
B45: ▪ | C45: Distribución de agua potable en PP-R de De20 a De40, oculta en plenum de plafón y ahogada en muro.
B46: ▪ | C46: Drenaje sanitario: colector de acero galvanizado con recubrimiento epóxico interior De110 y ramales de PVC De110, De75 y De50, con coladeras y registros de limpieza.
...

Sheet 4. EXCLUSIONES Y SUPUESTOS
A1: LESTRAL CONSTRUCTORA, S. DE R.L. DE C.V. | ELECTROMECÁNICA DEL PACÍFICO (EMP)
A2: 4. EXCLUSIONES, SUPUESTOS Y BASE DEL PRECIO
B4: EXCLUSIONES
B5: 1 | C5: Equipo de proceso y producción, y cualquier conexión de servicio aguas abajo de la válvula preinstalada o caja terminal que deja este contrato.
B6: 2 | C6: Tubería de ramales de aire comprimido aguas abajo de las ocho válvulas DN20 preinstaladas; compresor, secador, tanque y tren de tratamiento de aire.
B7: 3 | C7: Equipo de cabecera de baja tensión: servidor de CCTV, switches, NVR, servidor de control de acceso y enrolador, todos reutilizados de la instalación existente del cliente.
B8: 4 | C8: Mobiliario de oficina, estaciones de trabajo, lockers, gabinetes, lavabos del vestidor y botes de basura, según lo señalado en el catálogo del cliente.
B9: 5 | C9: Generación, almacenamiento y distribución de agua desionizada, purificada o de proceso.
B10: 6 | C10: Permisos, licencias y derechos municipales, estatales y federales; cuotas de conexión y cargos por demanda de la compañía suministradora.
B11: 7 | C11: Ampliación del servicio eléctrico aguas arriba del tablero general existente, incluyendo transformador de la compañía, medición y alimentador primario.
B12: 8 | C12: Refuerzo estructural de la losa, cimentación o cubierta del edificio existente más allá de la estructura metálica indicada en el proyecto ejecutivo.
B13: 9 | C13: Retiro, tratamiento o disposición de materiales peligrosos, asbesto o suelo contaminado que se descubran durante los trabajos.
B14: 10 | C14: Vestimenta de cuarto limpio, consumibles, filtros de repuesto adicionales al primer juego instalado, y capacitación de operadores más allá de la sesión de entrega.
B15: 11 | C15: Honorarios de organismos certificadores externos cuando el cliente decida designar un certificador independiente.
B16: 12 | C16: Impuestos de importación y gastos aduanales sobre equipo suministrado por el cliente.
B18: SUPUESTOS Y BASE DEL PRECIO
B19: 1 | C19: Todas las cantidades se toman del catálogo del cliente del 10-sep-2026 sin recuantificar. Las cantidades quedan sujetas a verificación contra los planos IFC durante la elaboración de planos de taller; las variaciones se liquidan a los precios unitarios de esta cotización.
B20: 2 | C20: Los precios unitarios son firmes por 30 días naturales y se expresan en dólares americanos. Cuando se requiere tipo de cambio de referencia para insumos en pesos, se utilizó 17.00 MXN por USD; el tipo de cambio se reconsidera a la firma del contrato.
B21: 3 | C21: Los precios incluyen material, mano de obra, equipo, herramienta, transporte, supervisión, indirectos de campo y las obligaciones de garantía del contratista, puesto en obra e instalado.
B22: 4 | C22: Acceso libre, seguro y continuo a las áreas de trabajo durante el horario acordado, con frente de trabajo despejado y área de maniobra adecuada dentro de la planta.
B23: 5 | C23: El servicio eléctrico existente tiene capacidad disponible suficiente en el tablero general para alimentar la nueva carga; esto se confirma mediante medición durante las primeras dos semanas y se reporta al cliente.
B24: 6 | C24: El equipo a 380 V especificado en el proyecto ejecutivo se cotiza tal como está diseñado, junto con el transformador reductor de 200 kVA necesario para alimentarlo.
B25: 7 | C25: El sistema de protección contra incendio se cotiza tal como está diseñado bajo normas GB. Se asume que la aprobación de la autoridad mexicana y de la aseguradora de la planta la obtiene el cliente sobre esa base, o bien se adopta la alternativa NFPA de la sección de Ingeniería de Valor.
B26: 8 | C26: La estructura, losa y cubierta del edificio se encuentran en buen estado y son capaces de recibir las nuevas cargas sin refuerzo distinto al indicado en los planos.
B27: 9 | C27: Los trabajos se ejecutan en un solo turno diurno, de lunes a sábado. En preliminares se lleva una provisión de trabajo nocturno y aceleración que se libera si se otorga acceso las 24 horas.
B28: 10 | C28: Aplica IVA del 8% conforme al estímulo fiscal de la Región Fronteriza Norte para Baja California.
B29: 11 | C29: Los cambios de alcance, cantidad o especificación se ejecutan contra orden de cambio firmada, a los precios unitarios aquí establecidos.

Sheet 5. DESGLOSE PARTIDAS
A1: LESTRAL CONSTRUCTORA, S. DE R.L. DE C.V. | ELECTROMECÁNICA DEL PACÍFICO (EMP)
A2: 5. DESGLOSE POR PARTIDAS — TODAS LAS CIFRAS EN USD
A3: CELDAS EDITABLES: columnas E y F (precio unitario de material e instalación), en azul. Todo lo demás está en fórmula y se actualiza automáticamente.
A5: CÓDIGO | B5: DESCRIPCIÓN | C5: UNIDAD | D5: CANTIDAD | E5: P.U. MATERIAL | F5: P.U. INSTALACIÓN | G5: P.U. TOTAL | H5: IMPORTE
A6: SECCIÓN A — 01 PRELIMINARES Y MEDIDAS DE CONSTRUCCIÓN
A7: A-001 | B7: Administración de obra: superintendente, coordinador de seguridad y administración de campo durante todo el periodo de construcción | C7: LOTE | D7: 1 | E7: 0 | F7: 46500 | G7: =E7+F7 -> 46500 | H7: =ROUND(D7*G7,2) -> 46500
A8: A-002 | B8: Instalaciones provisionales: montaje, uso y desmontaje de oficina de obra, almacén, área de cambio y servicios temporales | C8: LOTE | D8: 1 | E8: 0 | F8: 18500 | G8: =E8+F8 -> 18500 | H8: =ROUND(D8*G8,2) -> 18500
A9: A-003 | B9: Medidas de seguridad y vigilancia en obra: señalización, barreras, EPP, guardia contra incendio y control de acceso | C9: LOTE | D9: 1 | E9: 0 | F9: 12500 | G9: =E9+F9 -> 12500 | H9: =ROUND(D9*G9,2) -> 12500
A10: A-004 | B10: Descarga, recepción, resguardo y maniobra interna de equipos y materiales del cliente y del contratista | C10: LOTE | D10: 1 | E10: 0 | F10: 14000 | G10: =E10+F10 -> 14000 | H10: =ROUND(D10*G10,2) -> 14000
A11: A-005 | B11: Andamios y plataformas de trabajo en altura: montaje, desmontaje, renta, transporte y consumibles | C11: LOTE | D11: 1 | E11: 0 | F11: 16500 | G11: =E11+F11 -> 16500 | H11: =ROUND(D11*G11,2) -> 16500
A12: A-006 | B12: Consumo de servicios durante la construcción (energía eléctrica, agua, aire comprimido) | C12: LOTE | D12: 1 | E12: 0 | F12: 9500 | G12: =E12+F12 -> 9500 | H12: =ROUND(D12*G12,2) -> 9500
A13: A-007 | B13: Seguros de personal y equipo: responsabilidad civil, todo riesgo de construcción, IMSS y cuotas obrero-patronales | C13: LOTE | D13: 1 | E13: 0 | F13: 14500 | G13: =E13+F13 -> 14500 | H13: =ROUND(D13*G13,2) -> 14500
A14: A-008 | B14: Maniobras de izaje y grúa requeridas para la colocación de materiales y equipos | C14: LOTE | D14: 1 | E14: 0 | F14: 8500 | G14: =E14+F14 -> 8500 | H14: =ROUND(D14*G14,2) -> 8500
A15: A-009 | B15: Planos de taller, adecuación del paquete IFC a normativa mexicana (NOM-001-SEDE, NOM-002-STPS, NFPA) y elaboración de planos as-built | C15: LOTE | D15: 1 | E15: 0 | F15: 26500 | G15: =E15+F15 -> 26500 | H15: =ROUND(D15*G15,2) -> 26500
A16: A-010 | B16: Acarreo secundario de materiales y transporte interno dentro de la planta | C16: LOTE | D16: 1 | E16: 0 | F16: 6500 | G16: =E16+F16 -> 6500 | H16: =ROUND(D16*G16,2) -> 6500
A17: A-011 | B17: Niveles de proyecto, trazo, ejes y levantamiento topográfico | C17: LOTE | D17: 1 | E17: 0 | F17: 7500 | G17: =E17+F17 -> 7500 | H17: =ROUND(D17*G17,2) -> 7500
A18: A-012 | B18: Reporte diario de avance y registro fotográfico | C18: LOTE | D18: 1 | E18: 0 | F18: 4800 | G18: =E18+F18 -> 4800 | H18: =ROUND(D18*G18,2) -> 4800
... A28: A-022 | B28: Juegos de planos, transmittals y registros de aprobación firmados | C28: LOTE | D28: 1 | E28: 0 | F28: 4200 | G28: =E28+F28 -> 4200 | H28: =ROUND(D28*G28,2) -> 4200
A29: A TOTAL | B29: SUBTOTAL SECCIÓN A — 01 PRELIMINARES Y MEDIDAS DE CONSTRUCCIÓN | H29: =SUM(H7:H28) -> 266800
A31: SECCIÓN B — 02 ARQUITECTÓNICO, ESTRUCTURA Y ACABADOS
A32: B-001 | B32: Columnas de acero 200x200x6 Q235B equivalente ASTM A36/A572, incluye placas base, atiesadores, tornillos grado C y anclas, con primario de taller | C32: TON | D32: 6.386016 | E32: 2350 | F32: 920 | G32: =E32+F32 -> 3270 | H32: =ROUND(D32*G32,2) -> 20882.27
A33: B-002 | B33: Vigas de acero HM244x175x7x11 y HM294x200x8x12 equivalente Q235B, incluye conexiones y primario de taller | C33: TON | D33: 21.728 | E33: 2280 | F33: 880 | G33: =E33+F33 -> 3160 | H33: =ROUND(D33*G33,2) -> 68660.48
A34: B-003 | B34: Largueros, tensores rectos y diagonales, puntales y escaleras: canal, ángulo, tubo rectangular, placa y viga I | C34: TON | D34: 5.926 | E34: 2420 | F34: 1120 | G34: =E34+F34 -> 3540 | H34: =ROUND(D34*G34,2) -> 20978.04
A35: B-004 | B35: Placas e insertos ahogados según planos, incluye limpieza y primario anticorrosivo | C35: TON | D35: 0.994752 | E35: 2650 | F35: 1450 | G35: =E35+F35 -> 4100 | H35: =ROUND(D35*G35,2) -> 4078.48
A36: B-005 | B36: Tornillería estructural de alta resistencia M20 grado 10.9, incluye arandelas y registro de torque | C36: EQ | D36: 388 | E36: 4.6 | F36: 3.1 | G36: =E36+F36 -> 7.7 | H36: =ROUND(D36*G36,2) -> 2987.6
A37: B-006 | B37: Muro de block ligero de 200 mm con repellado de mortero cemento-arena, incluye anclaje, refuerzo, dala, reventón y dinteles | C37: M2 | D37: 159.5 | E37: 23.5 | F37: 29.5 | G37: =E37+F37 -> 53 | H37: =ROUND(D37*G37,2) -> 8453.5
A38: B-007 | B38: Muro de azulejo 300x600 mm en baños, adherido con pegazulejo especial sobre impermeabilizante de poliuretano de 1.5 mm | C38: M2 | D38: 200.8272 | E38: 27 | F38: 25 | G38: =E38+F38 -> 52 | H38: =ROUND(D38*G38,2) -> 10443.01
A39: B-008 | B39: Muro divisorio de panel sándwich para cuarto limpio, núcleo de lana mineral de 50 mm, incluye perfilería de aluminio y sellado total de juntas con silicón | C39: M2 | D39: 1127.992 | E39: 118 | F39: 44 | G39: =E39+F39 -> 162 | H39: =ROUND(D39*G39,2) -> 182734.7
A40: B-009 | B40: Malla de cerramiento con postes de PTR 50 mm a cada 2.5 m, alambre de malla no menor a 2.4 mm, incluye puerta y anclaje a piso | C40: ML | D40: 73.2348 | E40: 49 | F40: 23 | G40: =E40+F40 -> 72 | H40: =ROUND(D40*G40,2) -> 5272.91
A41: B-010 | B41: Piso de loseta antiderrapante 600x600 mm adherida con pegazulejo especial sobre impermeabilizante de poliuretano de 1.5 mm | C41: M2 | D41: 61.803 | E41: 28.5 | F41: 23 | G41: =E41+F41 -> 51.5 | H41: =ROUND(D41*G41,2) -> 3182.85
A42: B-011 | B42: Piedra de umbral incluye adhesivo, preparación de superficie, nivelación, biselado y pulido de canto | C42: M2 | D42: 1.2 | E42: 68 | F42: 32 | G42: =E42+F42 -> 100 | H42: =ROUND(D42*G42,2) -> 120
A43: B-012 | B43: Sistema de piso epóxico disipativo (ESD): primario epóxico, mortero epóxico, mortero epóxico antiestático, retícula de cobre y acabado epóxico | C43: M2 | D43: 646.3275 | E43: 59 | F43: 39 | G43: =E43+F43 -> 98 | H43: =ROUND(D43*G43,2) -> 63340.1
... A62: B-031 | B62: Demolición y reparación: muros, pisos y plafones de baños existentes; otros muros divisorios y plafones; reparación de piso igualando el acabado contiguo | C62: LOTE | D62: 1 | E62: 0 | F62: 29500 | G62: =E62+F62 -> 29500 | H62: =ROUND(D62*G62,2) -> 29500
A63: B TOTAL | B63: SUBTOTAL SECCIÓN B — 02 ARQUITECTÓNICO, ESTRUCTURA Y ACABADOS | H63: =SUM(H32:H62) -> 606786.77
A65: SECCIÓN C — 03 HVAC Y SISTEMAS DE AIRE DE CUARTO LIMPIO
A66: C-001 | B66: Fan coil de alta presión estática, 10.0 kW frío / 11.2 kW calor, 250 W, 1F 220V 60Hz, con bomba de condensados integrada | C66: EQ | D66: 12 | E66: 1180 | F66: 270 | G66: =E66+F66 -> 1450 | H66: =ROUND(D66*G66,2) -> 17400
A67: C-002 | B67: Fan coil de alta presión estática, 12.5 kW frío / 14.0 kW calor, 340 W, 1F 220V 60Hz, con bomba de condensados integrada | C67: EQ | D67: 1 | E67: 1420 | F67: 295 | G67: =E67+F67 -> 1715 | H67: =ROUND(D67*G67,2) -> 1715
A68: C-003 | B68: Unidad interior multi-split tipo cassette de 4 vías, 5.6 kW frío / 6.5 kW calor, 40 W, 1F 220V 60Hz | C68: EQ | D68: 1 | E68: 985 | F68: 225 | G68: =E68+F68 -> 1210 | H68: =ROUND(D68*G68,2) -> 1210
A69: C-004 | B69: Unidad condensadora exterior para el sistema de fan coils, 123.5 kW frío / 137.5 kW calor, 41.57 kW, 3F 60Hz, montada sobre base exterior | C69: EQ | D69: 1 | E69: 36500 | F69: 4300 | G69: =E69+F69 -> 40800 | H69: =ROUND(D69*G69,2) -> 40800
A70: C-005 | B70: Termostato de pared con control de temperatura ambiente | C70: PZA | D70: 14 | E70: 148 | F70: 46 | G70: =E70+F70 -> 194 | H70: =ROUND(D70*G70,2) -> 2716
...

Sheet 6. RESUMEN DE COSTOS
A1: LESTRAL CONSTRUCTORA, S. DE R.L. DE C.V. | ELECTROMECÁNICA DEL PACÍFICO (EMP)
A2: 6. RESUMEN DE COSTOS — TODAS LAS CIFRAS EN USD
B4: CONCEPTO | C4: TASA | D4: IMPORTE (USD) | E4: BASE DE CÁLCULO
B5: A. 01 PRELIMINARES Y MEDIDAS DE CONSTRUCCIÓN | D5: =SUMIF('5. DESGLOSE PARTIDAS'!$A:$A,"A TOTAL",'5. DESGLOSE PARTIDAS'!$H:$H) -> 266800 | E5: Suma de partidas cotizadas, hoja 5
B6: B. 02 ARQUITECTÓNICO, ESTRUCTURA Y ACABADOS | D6: =SUMIF('5. DESGLOSE PARTIDAS'!$A:$A,"B TOTAL",'5. DESGLOSE PARTIDAS'!$H:$H) -> 606786.77 | E6: Suma de partidas cotizadas, hoja 5
B7: C. 03 HVAC Y SISTEMAS DE AIRE DE CUARTO LIMPIO | D7: =SUMIF('5. DESGLOSE PARTIDAS'!$A:$A,"C TOTAL",'5. DESGLOSE PARTIDAS'!$H:$H) -> 365367 | E7: Suma de partidas cotizadas, hoja 5
B8: D. 04 INSTALACIONES ELÉCTRICAS | D8: =SUMIF('5. DESGLOSE PARTIDAS'!$A:$A,"D TOTAL",'5. DESGLOSE PARTIDAS'!$H:$H) -> 275378.78 | E8: Suma de partidas cotizadas, hoja 5
B9: E. 05 HIDRÁULICA, AGUA POTABLE Y DRENAJE | D9: =SUMIF('5. DESGLOSE PARTIDAS'!$A:$A,"E TOTAL",'5. DESGLOSE PARTIDAS'!$H:$H) -> 62252.99 | E9: Suma de partidas cotizadas, hoja 5
B10: F. 06 PROTECCIÓN CONTRA INCENDIO Y ALARMA | D10: =SUMIF('5. DESGLOSE PARTIDAS'!$A:$A,"F TOTAL",'5. DESGLOSE PARTIDAS'!$H:$H) -> 150728.24 | E10: Suma de partidas cotizadas, hoja 5
B11: G. 07 SISTEMAS DE TI, CCTV Y CONTROL DE ACCESO | D11: =SUMIF('5. DESGLOSE PARTIDAS'!$A:$A,"G TOTAL",'5. DESGLOSE PARTIDAS'!$H:$H) -> 34987.99 | E11: Suma de partidas cotizadas, hoja 5
B12: H. 08 DISTRIBUCIÓN DE AIRE COMPRIMIDO | D12: =SUMIF('5. DESGLOSE PARTIDAS'!$A:$A,"H TOTAL",'5. DESGLOSE PARTIDAS'!$H:$H) -> 30317.09 | E12: Suma de partidas cotizadas, hoja 5
B13: A. COSTO DIRECTO TOTAL | D13: =SUM(D5:D12) -> 1792618.9 | E13: Material más instalación, las 341 partidas, puesto en obra e instalado
B14: B. COSTO INDIRECTO (oficina central, fianzas, financiamiento) | C14: 0.08 | D14: =ROUND(D13*C14,2) -> 143409.51 | E14: 8% sobre el costo directo. Los indirectos de campo (supervisión, seguros, instalaciones provisionales, servicios) ya están cotizados en la Sección A, por lo que esta tasa cubre únicamente oficina central y evita duplicidad.
B15: C. SUBTOTAL (directo + indirecto) | D15: =D13+D14 -> 1936028.4
B16: D. UTILIDAD DEL CONTRATISTA | C16: 0.1 | D16: =ROUND(D15*C16,2) -> 193602.84 | E16: 10% sobre el subtotal anterior, estándar para obra industrial llave en mano de esta escala en Baja California.
B17: E. SUBTOTAL (directo + indirecto + utilidad) | D17: =D15+D16 -> 2129631.2
B18: F. CONTINGENCIA | C18: 0.03 | D18: =ROUND(D17*C18,2) -> 63888.94 | E18: 3% sobre el subtotal anterior. Cubre variación de cantidades al verificar contra planos IFC y condiciones imprevistas menores del edificio existente. La contingencia no ejercida se devuelve al cliente en el finiquito.
B19: G. TOTAL ANTES DE IVA | D19: =D17+D18 -> 2193520.1 | E19: Precio contractual sin impuesto
B20: H. IVA | C20: 0.08 | D20: =ROUND(D19*C20,2) -> 175481.61 | E20: 8% conforme al estímulo fiscal de la Región Fronteriza Norte para Baja California
B21: I. PRECIO TOTAL DEL CONTRATO (IVA incluido) | D21: =D19+D20 -> 2369001.8
B23: DESGLOSE MATERIAL / INSTALACIÓN
B24: Procura de material y equipo | D24: =SUMPRODUCT('5. DESGLOSE PARTIDAS'!$D$6:$D$371,'5. DESGLOSE PARTIDAS'!$E$6:$E$371) -> 963504.39 | E24: Columna D x columna E, hoja 5
B25: Trabajos de construcción e instalación | D25: =SUMPRODUCT('5. DESGLOSE PARTIDAS'!$D$6:$D$371,'5. DESGLOSE PARTIDAS'!$F$6:$F$371) -> 829114.48 | E25: Columna D x columna F, hoja 5

Sheet 7. CONDICIONES COMERCIALES
A1: LESTRAL CONSTRUCTORA, S. DE R.L. DE C.V. | ELECTROMECÁNICA DEL PACÍFICO (EMP)
A2: 7. CONDICIONES COMERCIALES
B4: 7.1 ESQUEMA DE PAGOS
B5: HITO | C5: % DEL PRECIO | D5: IMPORTE (USD) | E5: CONDICIÓN DE LIBERACIÓN
B6: Anticipo a la firma del contrato (semana 1) | C6: 0.3 | D6: =ROUND('6. RESUMEN DE COSTOS'!$D$21*C6,2) -> 710700.53 | E6: Contrato u orden de compra firmada, factura y fianza de anticipo si aplica
B7: Estimación 1 - estructura y muros (semana 7) | C7: 0.2 | D7: =ROUND('6. RESUMEN DE COSTOS'!$D$21*C7,2) -> 473800.35 | E7: Avance certificado, factura y reporte fotográfico
B8: Estimación 2 - instalación gruesa MEP terminada (semana 13) | C8: 0.25 | D8: =ROUND('6. RESUMEN DE COSTOS'!$D$21*C8,2) -> 592250.44 | E8: Avance certificado, factura y liberación de inspección de instalación gruesa
B9: Estimación 3 - acabados y equipos colocados (semana 18) | C9: 0.15 | D9: =ROUND('6. RESUMEN DE COSTOS'!$D$21*C9,2) -> 355350.26 | E9: Avance certificado, factura y reportes de pruebas
B10: Finiquito contra entrega y aceptación (semana 24) | C10: 0.1 | D10: =ROUND('6. RESUMEN DE COSTOS'!$D$21*C10,2) -> 236900.18 | E10: Acta de entrega-recepción, dossier de cierre y factura
B11: TOTAL | C11: =SUM(C6:C10) -> 1 | D11: =SUM(D6:D10) -> 2369001.8
B13: 7.2 VIGENCIA DE LA OFERTA Y MONEDA
B14: • Vigencia: 30 días naturales a partir del 10 de septiembre de 2026. Después de esa fecha los precios quedan sujetos a revisión contra las cotizaciones de proveedor vigentes.
B15: • Moneda: dólares americanos (USD). Todos los pagos se realizan en USD. Cuando se requiere tipo de cambio de referencia para insumos en pesos, se utilizó 17.00 MXN/USD, que se reconsidera a la firma del contrato.
B16: • Los precios son unitarios, firmes durante la vigencia, e incluyen material, mano de obra, equipo, herramienta, transporte, supervisión e indirectos de campo, puesto en obra e instalado.
B17: • Aplica IVA del 8% conforme al estímulo fiscal de la Región Fronteriza Norte para Baja California y se muestra por separado en el resumen de costos.
B19: 7.3 ANTICIPO Y ESTIMACIONES
B20: • Anticipo: 30% del precio del contrato a la firma, contra factura y, si el cliente lo requiere, fianza de anticipo emitida por afianzadora mexicana.
B21: • El anticipo se amortiza proporcionalmente en cada estimación de avance posterior.
B22: • Las estimaciones de avance se presentan mensualmente, certificadas de manera conjunta por el representante del cliente y el superintendente de EMP, soportadas con cantidades medidas y reporte fotográfico.
B23: • Plazo de pago: 7 días hábiles a partir de la aceptación de la estimación certificada y la recepción de factura válida. Finiquito: 10 días hábiles.
B24: • Retención: el cliente puede retener 5% de cada estimación, liberable contra el acta de entrega-recepción, o sustituirla por fianza de cumplimiento de valor equivalente.
B26: 7.4 GARANTÍAS
... B49: Lestral Constructora / Electromecánica del Pacífico (EMP) — Responsable técnico y punto único de contacto

Sheet 8. PROGRAMA GANTT
A1: LESTRAL CONSTRUCTORA, S. DE R.L. DE C.V. | ELECTROMECÁNICA DEL PACÍFICO (EMP)
A2: 8. PROGRAMA DE OBRA — GANTT SEMANAL CON RUTA CRÍTICA E HITOS
B4: Duración 24 semanas a partir del anticipo. Simbología: ■ ruta crítica ■ actividad no crítica ◆ hito ▲ hito de pago
B6: # | C6: ACTIVIDAD | D6: RUTA | E6: 1 | F6: 2 | G6: 3 | H6: 4 | I6: 5 | J6: 6 | K6: 7 | L6: 8 | M6: 9 | N6: 10 | O6: 11 | P6: 12 | Q6: 13 | R6: 14 | S6: 15 | T6: 16 | U6: 17 | V6: 18 | W6: 19 | X6: 20 | Y6: 21 | Z6: 22 | AA6: 23 | AB6: 24
B7: 1 | C7: Adjudicación, movilización y entrega de submittals | D7: RC
B8: 2 | C8: Procura de equipo de largo plazo (VRF, UMA de expansión directa, tableros, transformador) | D8: RC
B9: 3 | C9: Planos de taller y adecuación normativa NOM | D9: RC
B10: 4 | C10: Demolición y desmantelamiento de instalaciones existentes | D10: RC
B11: 5 | C11: Ranurado en muro y piso, barrenos | D11: —
B12: 6 | C12: Fabricación en taller de estructura metálica | D12: —
B13: 7 | C13: Montaje de estructura metálica | D13: RC
B14: 8 | C14: Muros de block y albañilería | D14: —
B15: 9 | C15: Instalación gruesa de ductos HVAC | D15: RC
B16: 10 | C16: Tubería de refrigerante y condensados | D16: —
B17: 11 | C17: Instalación gruesa de charola, conduit y cableado | D17: —
B18: 12 | C18: Tubería de rociadores e hidrantes | D18: —
... B32: 26 | C32: Lista de detalles, limpieza fina, as-builts y entrega | D32: RC
B34: HITOS DEL PROYECTO
B35: H1 Adjudicación y anticipo | E35: ◆
B36: H2 Planos de taller aprobados | H36: ◆
B37: H3 Estructura y muros terminados | R37: ◆
B38: H4 Instalación gruesa MEP terminada | T38: ◆
B39: H5 Energización y arranque de equipos | W39: ◆
B40: H6 Puesta en servicio terminada | Y40: ◆
B41: H7 Terminación sustancial y entrega | AB41: ◆
B43: HITOS DE PAGO
B44: Anticipo a la firma del contrato (30%) | E44: ▲
B45: Estimación 1 - estructura y muros (20%) | K45: ▲
B46: Estimación 2 - instalación gruesa MEP terminada (25%) | Q46: ▲
B47: Estimación 3 - acabados y equipos colocados (15%) | V47: ▲
B48: Finiquito contra entrega y aceptación (10%) | AB48: ▲
B50: Ruta crítica: adjudicación y movilización → procura de equipo de largo plazo → planos de taller y adecuación NOM → demolición → montaje de estructura → instalación gruesa de ductos HVAC → muro de panel de cuarto limpio → plafón de panel de cuarto limpio → colocación de equipos HVAC → piso epóxico → puesta en servicio y balanceo → calificación de cuarto limpio → entrega. La procura de la condensadora de 123.5 kW, la manejadora de expansión directa y el transformador de 200 kVA gobierna las primeras diez semanas; las medidas de Ingeniería de Valor de la hoja 9 sacan de esa ruta crítica al transformador y a los materiales de consumo importados.

Sheet 9. INGENIERIA DE VALOR
A1: LESTRAL CONSTRUCTORA, S. DE R.L. DE C.V. | ELECTROMECÁNICA DEL PACÍFICO (EMP)
A2: 9. INGENIERÍA DE VALOR PROPUESTA POR EMP
B4: La cotización base cotiza el proyecto ejecutivo exactamente como está diseñado. Las alternativas siguientes son propuestas de EMP; ninguna se aplicó al precio base. Cada una se cuantifica por separado para que el cliente la acepte o rechace por sus propios méritos. Los ahorros se calculan sobre las partidas afectadas de la hoja 5.
B7: 9.1 ALTERNATIVAS DE REDUCCIÓN DE COSTO
B8: REF | C8: ALTERNATIVA | D8: IMPACTO EN PLAZO | E8: AHORRO ESTIMADO (USD) | F8: IMPACTO EN DESEMPEÑO
B9: VE-01 | C9: Reespecificar equipos y tableros a 480/277-220 V, 60 Hz (NEMA/NOM) y eliminar el transformador de 200 kVA 480/380 V | D9: -2 semanas | E9: 15400 | F9: Cumplimiento nativo de NOM-001-SEDE; elimina ~2% de pérdidas por transformación y un punto único de falla; refacciones locales en vez de importadas
B10: VE-02 | C10: Sustituir canalización, conductor y tubería hidráulica de norma GB por equivalentes norteamericanos (JDG/SC a EMT/RMC, cable GB a THHN/XHHW, PP-R a CPVC) | D10: -4 semanas | E10: 13287.63 | F10: Desempeño igual o superior, con listado UL y certificación NOM; elimina 8-12 semanas de importación y la exposición aduanal en materiales de consumo
B11: VE-03 | C11: Convertir el diseño contra incendio GB a cálculo hidráulico NFPA 13 / NFPA 14 con rociadores K5.6 y una sola columna combinada para rociadores e hidrantes | D11: -1 semanas | E11: 13295.04 | F11: Diseño asegurable (FM/NFPA) aceptado por la autoridad mexicana y por la aseguradora de la planta; elimina el riesgo de reinspección y retrabajo de una entrega solo GB
B12: VE-04 | C12: Limitar el plafón sándwich transitable de cuarto limpio a las áreas clasificadas; plafón suspendido estándar en oficinas, vestidor y áreas de apoyo | D12: -1 semanas | E12: 20302.49 | F12: Sin efecto en la clasificación ISO: las áreas afectadas están fuera de la envolvente clasificada y no tienen requisito de cascada de presión
B13: VE-05 | C13: Aplicar epóxico ESD únicamente en las áreas con requisito electrostático declarado; epóxico estándar en el resto | D13: neutro | E13: 6948.02 | F13: Requiere confirmación por escrito del límite de la zona ESD por parte del cliente; el desempeño ESD no cambia dentro de la zona declarada
B14: VE-06 | C14: Utilizar ducto de panel fenólico preaislado en los tramos de aire exterior y extracción no clasificados, en vez de ducto galvanizado con aislamiento exterior | D14: -1 semanas | E14: 2136.42 | F14: Menor clase de fuga y mejor desempeño térmico; se fabrica en sitio, lo que saca la cola del taller de lámina de la ruta crítica
B15: VE-07 | C15: Liberar la provisión de trabajo nocturno y aceleración a cambio de acceso al sitio 24 horas y frente de trabajo libre | D15: neutro | E15: 9500 | F15: Requiere que el cliente otorgue acceso sin restricción; si el acceso permanece limitado a un turno, la provisión debe restituirse
B16: Σ | C16: AHORRO TOTAL IDENTIFICADO SOBRE COSTO DIRECTO | D16: -4 semanas | E16: =SUM(E9:E15) -> 80869.6
B18: 9.2 ALTERNATIVAS DE DESEMPEÑO (costo de capital adicional, reducción de costo de operación)
B19: REF | C19: ALTERNATIVA | D19: CAPEX ADICIONAL (USD) | E19: AHORRO ANUAL DE OPERACIÓN (USD) | F19: IMPACTO EN DESEMPEÑO
B20: VE-08 | C20: Banco VRF con recuperación de calor en lugar de dos unidades condensadoras independientes | D20: 11500 | E20: 8600 | F20: Transfiere calor entre zonas que piden frío y calor de forma simultánea; retorno aproximado de 1.3 años
B21: VE-09 | C21: Rueda entálpica de recuperación en la unidad de aire exterior de 2,500 m3/h | D21: 6800 | E21: 5400 | F21: Recupera aproximadamente el 65% de la carga entálpica de aire exterior; retorno aproximado de 1.3 años y reduce la demanda pico
B22: VE-10 | C22: Control de atenuación 0-10 V y sensores de ocupación en el alumbrado de áreas no clasificadas | D22: 0 | E22: 3200 | F22: Sin impacto de costo de capital si se especifica desde la compra; reduce el consumo de alumbrado aproximadamente 35% en áreas de ocupación intermitente
B23: Σ | C23: TOTAL | D23: =SUM(D20:D22) -> 18300 | E23: =SUM(E20:E22) -> 17200
B25: Recomendación de EMP: VE-01, VE-02 y VE-03 deben tratarse como asuntos de cumplimiento y no como ahorros opcionales. La tensión de distribución de 380 V no existe en la red mexicana, y el diseño contra incendio GB no es la base sobre la cual la autoridad local o la aseguradora de planta aprobarán la instalación. Adoptar las tres en conjunto saca de la ruta crítica al transformador, a los materiales de consumo importados y al riesgo de reingreso de trámite, y es el mayor contribuyente individual tanto a la reducción de costo como a la de plazo que se muestra en la hoja 10.

Sheet 10. BASE VS OPTIMIZADO
A1: LESTRAL CONSTRUCTORA, S. DE R.L. DE C.V. | ELECTROMECÁNICA DEL PACÍFICO (EMP)
A2: 10. COMPARATIVO DE ESCENARIOS — ESCENARIO BASE VS ESCENARIO OPTIMIZADO
B4: Escenario base: el proyecto ejecutivo cotizado exactamente como está diseñado. Escenario optimizado: el escenario base con las siete alternativas de reducción de costo de la hoja 9.1 adoptadas.
B6: CONCEPTO | C6: ESCENARIO BASE | D6: ESCENARIO OPTIMIZADO | E6: DIFERENCIA
B7: Costo directo | C7: ='6. RESUMEN DE COSTOS'!D13 -> 1792618.9 | D7: =C7-'9. INGENIERIA DE VALOR'!E16 -> 1711749.3 | E7: =D7-C7 -> -80869.6
B8: Costo indirecto (8%) | C8: =ROUND(C7*'6. RESUMEN DE COSTOS'!C14,2) -> 143409.51 | D8: =ROUND(D7*'6. RESUMEN DE COSTOS'!C14,2) -> 136939.94 | E8: =D8-C8 -> -6469.57
B9: Utilidad (10%) | C9: =ROUND((C7+C8)*'6. RESUMEN DE COSTOS'!C16,2) -> 193602.84 | D9: =ROUND((D7+D8)*'6. RESUMEN DE COSTOS'!C16,2) -> 184868.92 | E9: =D9-C9 -> -8733.92
B10: Contingencia (3%) | C10: =ROUND((C7+C8+C9)*'6. RESUMEN DE COSTOS'!C18,2) -> 63888.94 | D10: =ROUND((D7+D8+D9)*'6. RESUMEN DE COSTOS'!C18,2) -> 61006.74 | E10: =D10-C10 -> -2882.2
B11: TOTAL ANTES DE IVA | C11: =C7+C8+C9+C10 -> 2193520.1 | D11: =D7+D8+D9+D10 -> 2094564.9 | E11: =D11-C11 -> -98955.29
B12: IVA 8% | C12: =ROUND(C11*'6. RESUMEN DE COSTOS'!C20,2) -> 175481.61 | D12: =ROUND(D11*'6. RESUMEN DE COSTOS'!C20,2) -> 167565.19 | E12: =D12-C12 -> -7916.42
B13: PRECIO TOTAL DEL CONTRATO | C13: =C11+C12 -> 2369001.8 | D13: =D11+D12 -> 2262130 | E13: =D13-C13 -> -106871.71
B14: Ahorro como % del precio del contrato | C14: 0 | D14: =-E13/C13 -> 0.04511255 | E14: =D14 -> 0.04511255
B15: Plazo de construcción (semanas) | C15: 24 | D15: 20 | E15: -4
B16: Ahorro anual de operación (si se adopta 9.2) | C16: 0 | D16: ='9. INGENIERIA DE VALOR'!E23 -> 17200 | E16: =D16 -> 17200
B18: BENEFICIOS DEL ESCENARIO OPTIMIZADO
B19: • Los equipos operan a una tensión de distribución que sí existe en México, por lo que refacciones, servicio y ampliaciones futuras se consiguen localmente en vez de importarse.
B20: • El transformador de 200 kVA desaparece del cuarto eléctrico, junto con sus pérdidas permanentes, su espacio ocupado y sus 10 a 12 semanas de entrega.
B21: • Los materiales de consumo (tubería conduit, conductor, tubería hidráulica) pasan a tener listado UL y certificación NOM, lo que saca de la ruta crítica la exposición aduanal y de tiempo de entrega.
B22: • El sistema de protección contra incendio se vuelve asegurable en base NFPA, que es lo que en realidad revisarán tanto la autoridad mexicana como la aseguradora de planta.
B23: • Se recuperan cuatro semanas de la ruta crítica, lo que adelanta el arranque de producción aproximadamente un mes.
B24: • La clasificación del cuarto limpio, la cascada de presión, los cambios de aire por hora y el desempeño ESD dentro de la zona declarada no cambian en ningún aspecto.

Sheet 11. FORMATO BOQ CLIENTE
A1: LESTRAL CONSTRUCTORA, S. DE R.L. DE C.V. | ELECTROMECÁNICA DEL PACÍFICO (EMP)
A2: 11. RESUMEN DE COSTOS MAPEADO AL FORMATO DEL BOQ DEL CLIENTE (hoja 01.Summary)
B4: El mismo precio, presentado en la estructura de resumen del propio cliente para que ambos documentos se concilien línea por línea.
B6: No. | C6: DESCRIPCIÓN DE LA PARTIDA | D6: CONSTRUCCIÓN E INSTALACIÓN (USD) | E6: PROCURA DE EQUIPO (USD) | F6: COSTO TOTAL (USD)
B7: 1 | C7: Costo de medidas de construcción | D7: =SUMPRODUCT('5. DESGLOSE PARTIDAS'!$D$7:$D$28,'5. DESGLOSE PARTIDAS'!$F$7:$F$28) -> 266800 | E7: =SUMPRODUCT('5. DESGLOSE PARTIDAS'!$D$7:$D$28,'5. DESGLOSE PARTIDAS'!$E$7:$E$28) -> 0 | F7: =D7+E7 -> 266800
B8: 2 | C8: Arquitectónico y acabados | D8: =SUMPRODUCT('5. DESGLOSE PARTIDAS'!$D$32:$D$62,'5. DESGLOSE PARTIDAS'!$F$32:$F$62) -> 198570.57 | E8: =SUMPRODUCT('5. DESGLOSE PARTIDAS'!$D$32:$D$62,'5. DESGLOSE PARTIDAS'!$E$32:$E$62) -> 408216.21 | F8: =D8+E8 -> 606786.78
B9: 3 | C9: Obra de HVAC | D9: =SUMPRODUCT('5. DESGLOSE PARTIDAS'!$D$66:$D$176,'5. DESGLOSE PARTIDAS'!$F$66:$F$176) -> 121764.52 | E9: =SUMPRODUCT('5. DESGLOSE PARTIDAS'!$D$66:$D$176,'5. DESGLOSE PARTIDAS'!$E$66:$E$176) -> 243602.47 | F9: =D9+E9 -> 365366.99
B10: 4 | C10: Obra hidrosanitaria | D10: =SUMPRODUCT('5. DESGLOSE PARTIDAS'!$D$246:$D$280,'5. DESGLOSE PARTIDAS'!$F$246:$F$280) -> 26629.037 | E10: =SUMPRODUCT('5. DESGLOSE PARTIDAS'!$D$246:$D$280,'5. DESGLOSE PARTIDAS'!$E$246:$E$280) -> 35623.958 | F10: =D10+E10 -> 62252.995
B11: 5 | C11: Obra de protección contra incendio | D11: =SUMPRODUCT('5. DESGLOSE PARTIDAS'!$D$284:$D$334,'5. DESGLOSE PARTIDAS'!$F$284:$F$334) -> 74581.988 | E11: =SUMPRODUCT('5. DESGLOSE PARTIDAS'!$D$284:$D$334,'5. DESGLOSE PARTIDAS'!$E$284:$E$334) -> 76146.258 | F11: =D11+E11 -> 150728.25
B12: 6 | C12: Obra eléctrica | D12: =SUMPRODUCT('5. DESGLOSE PARTIDAS'!$D$180:$D$242,'5. DESGLOSE PARTIDAS'!$F$180:$F$242) -> 112676.91 | E12: =SUMPRODUCT('5. DESGLOSE PARTIDAS'!$D$180:$D$242,'5. DESGLOSE PARTIDAS'!$E$180:$E$242) -> 162701.87 | F12: =D12+E12 -> 275378.79
B13: 7 | C13: Obra de baja tensión | D13: =SUMPRODUCT('5. DESGLOSE PARTIDAS'!$D$338:$D$357,'5. DESGLOSE PARTIDAS'!$F$338:$F$357) -> 17064.51 | E13: =SUMPRODUCT('5. DESGLOSE PARTIDAS'!$D$338:$D$357,'5. DESGLOSE PARTIDAS'!$E$338:$E$357) -> 17923.479 | F13: =D13+E13 -> 34987.988
B14: 8 | C14: Obra de aire comprimido | D14: =SUMPRODUCT('5. DESGLOSE PARTIDAS'!$D$361:$D$368,'5. DESGLOSE PARTIDAS'!$F$361:$F$368) -> 11026.943 | E14: =SUMPRODUCT('5. DESGLOSE PARTIDAS'!$D$361:$D$368,'5. DESGLOSE PARTIDAS'!$E$361:$E$368) -> 19290.147 | F14: =D14+E14 -> 30317.09
B15: 9 | C15: Flete y logística | D15: 0 | E15: 0 | F15: Incluido en los precios unitarios; no se lleva flete de importación por separado
B16: 10 | C16: Pedimento y gastos aduanales | D16: 0 | E16: 0 | F16: No aplica: los materiales se adquieren en el mercado nacional
B17: 11 | C17: Honorarios de administración del proyecto | D17: ='6. RESUMEN DE COSTOS'!D14+'6. RESUMEN DE COSTOS'!D16+'6. RESUMEN DE COSTOS'!D18 -> 400901.29 | E17: 0 | F17: =D17+E17 -> 400901.29
B18: 12 | C18: Subtotal antes de IVA | D18: =SUM(D7:D17) -> 1230015.8 | E18: =SUM(E7:E17) -> 963504.39 | F18: =D18+E18 -> 2193520.2
B19: 13 | C19: IVA 8% | F19: =ROUND(F18*'6. RESUMEN DE COSTOS'!C20,2) -> 175481.61
B20: 14 | C20: PRECIO TOTAL (USD) | F20: =F18+F19 -> 2369001.8
B22: La línea 11 concentra el costo indirecto, la utilidad y la contingencia de la hoja 6 agrupados como honorario de administración del proyecto, que es el equivalente más cercano en la plantilla del cliente. El total de la línea 14 es idéntico al precio total del contrato de la hoja 6.
